Workbook

Sheet Overall
B2: SUMMARY
H3: Share price | K3: Profit Margins | T3: Valuations Multiples | AC3: Solvency | AL3: Efficiency | AU3: Risk
H4: CAGR | K4: GPM | N4: OM | Q4: NPM | T4: PE | W4: EPS | Z4: Dividend Yield | AC4: Debt Ratio | AF4: Debt - Equity | AI4: Debt - Revenue | AL4: IT | AO4: RT | AR4: PT | AU4: Sharpe Ratio | AX4: Sortino Ratio
B5: Base year | D5: Y/E | E5: Updated As At | F5: MC | G5: Share price at Y/E | H5: Current | I5: 3 years | J5: 5 years | K5: Current | L5: 3 years | M5: 5 years | N5: Current | O5: 3 years | P5: 5 years | Q5: Current | R5: 3 years | S5: 5 years | T5: Current | U5: 3 years | V5: 5 years | W5: Current | X5: 3 years | Y5: 5 years | Z5: Current | AA5: 3 years | AB5: 5 years | AC5: Current | AD5: 3 years | AE5: 5 years | AF5: Current | AG5: 3 years | AH5: 5 years | AI5: Current | AJ5: 3 years | AK5: 5 years | AL5: Current | AM5: 3 years | AN5: 5 years | AO5: Current | AP5: 3 years | AQ5: 5 years | AR5: Current | AS5: 3 years | AT5: 5 years | AU5: Current | AV5: 3 years | AW5: 5 years | AX5: Current | AY5: 3 years | AZ5: 5 years
B6: 2023 | D6: 31/12 | E6: 2023 | F6: =OFFSET(FS!P123,0,E$6-B$6) -> 1655842.1 | G6: =OFFSET(FS!P117,0,E$6-B$6) -> 151.94 | H6: =((OFFSET(FS!P$117,0,E$6-B$6)/OFFSET(FS!P$117,0,-1+E$6-B$6))^(1/1)-1)*100 -> 80.880952 | I6: =((OFFSET(FS!P$117,0,E$6-B$6)/OFFSET(FS!P$117,0,-2+E$6-B$6))^(1/3)-1)*100 -> -3.4162991 | J6: =((OFFSET(FS!P$117,0,E$6-B$6)/OFFSET(FS!P$117,0,-4+E$6-B$6))^(1/5)-1)*100 -> 10.473077 | K6: =OFFSET(FS!P$91,0,0+E$6-B$6) -> 46.982089 | L6: =AVERAGE(OFFSET(FS!P$91,0,-2+E$6-B$6):OFFSET(FS!P$91,0,E$6-B$6)) -> 44.273314 | M6: =AVERAGE(OFFSET(FS!P$91,0,-4+E$6-B$6):OFFSET(FS!P$91,0,E$6-B$6)) -> 42.675549 | N6: =OFFSET(FS!P$101,0,0+E$6-B$6) -> 6.4114408 | O6: =AVERAGE(OFFSET(FS!P$101,0,-2+E$6-B$6):OFFSET(FS!P$101,0,E$6-B$6)) -> 4.6966029 | P6: =AVERAGE(OFFSET(FS!P$101,0,-4+E$6-B$6):OFFSET(FS!P$101,0,E$6-B$6)) -> 5.0409519 | Q6: =OFFSET(FS!P$110,0,0+E$6-B$6) -> 5.2932836 | R6: =AVERAGE(OFFSET(FS!P$110,0,-2+E$6-B$6):OFFSET(FS!P$110,0,E$6-B$6)) -> 3.9550357 | S6: =AVERAGE(OFFSET(FS!P$110,0,-4+E$6-B$6):OFFSET(FS!P$110,0,E$6-B$6)) -> 4.3042454 | T6: =OFFSET(FS!P$119,0,0+E$6-B$6) -> 54.423734 | U6: =AVERAGE(OFFSET(FS!P$119,0,-2+E$6-B$6):OFFSET(FS!P$119,0,E$6-B$6)) -> 36.074788 | V6: =AVERAGE(OFFSET(FS!P$119,0,-4+E$6-B$6):OFFSET(FS!P$119,0,E$6-B$6)) -> 54.487092 | W6: =OFFSET(FS!P$118,0,0+E$6-B$6) -> 2.7917967 | X6: =AVERAGE(OFFSET(FS!P$118,0,-2+E$6-B$6):OFFSET(FS!P$118,0,E$6-B$6)) -> 1.891096 | Y6: =AVERAGE(OFFSET(FS!P$118,0,-4+E$6-B$6):OFFSET(FS!P$118,0,E$6-B$6)) -> 1.7618388 | Z6: =OFFSET(FS!P$129,0,0+E$6-B$6) -> 0 | AA6: =AVERAGE(OFFSET(FS!P$129,0,-2+E$6-B$6):OFFSET(FS!P$129,0,E$6-B$6)) -> 0 | AB6: =AVERAGE(OFFSET(FS!P$129,0,-4+E$6-B$6):OFFSET(FS!P$129,0,E$6-B$6)) -> 0 | AC6: =OFFSET(FS!P$175,0,0+E$6-B$6) -> 0.61755523 | AD6: =AVERAGE(OFFSET(FS!P$175,0,-2+E$6-B$6):OFFSET(FS!P$175,0,E$6-B$6)) -> 0.65772698 | AE6: =AVERAGE(OFFSET(FS!P$175,0,-4+E$6-B$6):OFFSET(FS!P$175,0,E$6-B$6)) -> 0.68137217 | AF6: =OFFSET(FS!P$176,0,0+E$6-B$6) -> 1.6147567 | AG6: =AVERAGE(OFFSET(FS!P$176,0,-2+E$6-B$6):OFFSET(FS!P$176,0,E$6-B$6)) -> 1.9416287 | AH6: =AVERAGE(OFFSET(FS!P$176,0,-4+E$6-B$6):OFFSET(FS!P$176,0,E$6-B$6)) -> 2.1786355 | AI6: =OFFSET(FS!P$177,0,0+E$6-B$6) -> 0.56713206 | AJ6: =AVERAGE(OFFSET(FS!P$177,0,-2+E$6-B$6):OFFSET(FS!P$177,0,E$6-B$6)) -> 0.59468079 | AK6: =AVERAGE(OFFSET(FS!P$177,0,-4+E$6-B$6):OFFSET(FS!P$177,0,E$6-B$6)) -> 0.59116129 | AL6: =OFFSET(FS!P$180,0,0+E$6-B$6) -> 9.1463773 | AM6: =AVERAGE(OFFSET(FS!P$180,0,-2+E$6-B$6):OFFSET(FS!P$180,0,E$6-B$6)) -> 8.6284266 | AN6: =AVERAGE(OFFSET(FS!P$180,0,-4+E$6-B$6):OFFSET(FS!P$180,0,E$6-B$6)) -> 8.7532527 | AO6: =OFFSET(FS!P$181,0,0+E$6-B$6) -> 11.000038 | AP6: =AVERAGE(OFFSET(FS!P$181,0,-2+E$6-B$6):OFFSET(FS!P$181,0,E$6-B$6)) -> 12.472646 | AQ6: =AVERAGE(OFFSET(FS!P$181,0,-4+E$6-B$6):OFFSET(FS!P$181,0,E$6-B$6)) -> 13.324991 | AR6: =OFFSET(FS!P$182,0,0+E$6-B$6) -> 3.5859663 | AS6: =AVERAGE(OFFSET(FS!P$182,0,-2+E$6-B$6):OFFSET(FS!P$182,0,E$6-B$6)) -> 3.5588713 | AT6: =AVERAGE(OFFSET(FS!P$182,0,-4+E$6-B$6):OFFSET(FS!P$182,0,E$6-B$6)) -> 3.4802587 | AU6: ='Sharpe, Sortino'!O23 -> 1.561188 | AV6: ='Sharpe, Sortino'!P23 -> -0.12295655 | AW6: ='Sharpe, Sortino'!Q23 -> 0.29297356 | AX6: ='Sharpe, Sortino'!O40 -> 24.748212 | AY6: ='Sharpe, Sortino'!P40 -> -0.22680311 | AZ6: ='Sharpe, Sortino'!Q40 -> 0.57295928

Sheet FS
F1: < Figures are in millions >
F2: Y/E 31/12 | U2: Annualized
F3: 2013 | G3: 2014 | H3: 2015 | I3: 2016 | J3: 2017 | K3: 2018 | L3: 2019 | M3: 2020 | N3: 2021 | O3: 2022 | P3: 2023 | R3: Average | S3: Median | T3: CAGR | U3: Std Dev
B5: Revenue by Geography
C6: United States | F6: 43959 | G6: 54717 | H6: 70537 | I6: 90349 | J6: 120486 | K6: 160146 | L6: 193636 | M6: 263520 | N6: 314006 | O6: 356113 | P6: 395637
C7: Germany | F7: 10535 | G7: 11919 | H7: 11816 | I7: 14148 | J7: 16951 | K7: 19881 | L7: 22232 | M7: 29565 | N7: 37326 | O7: 33598 | P7: 37588
C8: United Kingdom | F8: 7291 | G8: 8341 | H8: 9033 | I8: 9547 | J8: 11372 | K8: 14524 | L8: 17527 | M8: 26483 | N8: 31914 | O8: 30074 | P8: 33591
C9: Japan | F9: 7639 | G9: 7912 | H9: 8264 | I9: 10797 | J9: 11907 | K9: 13829 | L9: 16002 | M9: 20461 | N9: 23071 | O9: 24396 | P9: 26002
C10: Rest of World | F10: 5028 | G10: 6099 | H10: 7356 | I10: 11146 | J10: 17150 | K10: 24507 | L10: 31125 | M10: 46035 | N10: 63505 | O10: 69802 | P10: 81967
B11: Total Revenues | F11: =SUM(F6:F10) -> 74452 | G11: =SUM(G6:G10) -> 88988 | H11: =SUM(H6:H10) -> 107006 | I11: =SUM(I6:I10) -> 135987 | J11: =SUM(J6:J10) -> 177866 | K11: =SUM(K6:K10) -> 232887 | L11: =SUM(L6:L10) -> 280522 | M11: =SUM(M6:M10) -> 386064 | ... P11: =SUM(P6:P10) -> 574785
B13: Revenue By Specific Segments
C14: Online Stores | F14: =48802+21716 -> 70518 | G14: 68513 | H14: 76863 | I14: 91431 | J14: 108354 | K14: 122987 | L14: 141247 | M14: 197346 | N14: 222075 | O14: 220004 | P14: 231872
C15: Physical Stores | F15: 0 | G15: 0 | H15: 0 | I15: 0 | J15: 5798 | K15: 17224 | L15: 17192 | M15: 16227 | N15: 17075 | O15: 18963 | P15: 20030
C16: Third Party seller services | F16: 0 | G16: 11747 | H16: 16086 | I16: 22993 | J16: 31881 | K16: 42745 | L16: 53762 | M16: 80461 | N16: 103366 | O16: 117716 | P16: 140053
C17: Advertising services | F17: 826 | G17: 1322 | H17: 1710 | I17: 2950 | J17: 4653 | K17: 10108 | L17: 19210 | M17: 25207 | N17: 31160 | O17: 37739 | P17: 46906
C18: Subscription services | F18: 0 | G18: 2762 | H18: 4467 | I18: 6394 | J18: 9721 | K18: 14168 | L18: 12625 | M18: 19773 | N18: 31768 | O18: 35218 | P18: 40209
C19: AWS | F19: 3108 | G19: 4644 | H19: 7880 | I19: 12219 | J19: 17459 | K19: 25655 | L19: 35026 | M19: 45370 | N19: 62202 | O19: 80096 | P19: 90757
C20: Other | G20: 0 | H20: 0 | I20: 0 | J20: 0 | K20: 0 | L20: 1460 | M20: 1680 | N20: 2176 | O20: 4247 | P20: 4958
B21: Total Revenues | F21: =SUM(F14:F20) -> 74452 | G21: =SUM(G14:G20) -> 88988 | H21: =SUM(H14:H20) -> 107006 | I21: =SUM(I14:I20) -> 135987 | J21: =SUM(J14:J20) -> 177866 | K21: =SUM(K14:K20) -> 232887 | L21: =SUM(L14:L20) -> 280522 | M21: =SUM(M14:M20) -> 386064 | ... P21: =SUM(P14:P20) -> 574785
B23: Revenue By Broad Segments
C24: North America | F24: 41410 | G24: 50834 | H24: 63708 | I24: 79785 | J24: 106110 | K24: 141366 | L24: 170773 | M24: 236282 | N24: 279833 | O24: 315880 | P24: 352828
C25: International | F25: 29934 | G25: 33510 | H25: 35418 | I25: 43983 | J25: 54297 | K25: 65866 | L25: 74723 | M25: 104412 | N25: 127787 | O25: 118007 | P25: 131200
C26: AWS (Global) | F26: 3108 | G26: 4644 | H26: 7880 | I26: 12219 | J26: 17459 | K26: 25655 | L26: 35026 | M26: 45370 | N26: 62202 | O26: 80096 | P26: 90757
B27: Total Revenues | F27: =SUM(F24:F26) -> 74452 | G27: =SUM(G24:G26) -> 88988 | H27: =SUM(H24:H26) -> 107006 | I27: =SUM(I24:I26) -> 135987 | J27: =SUM(J24:J26) -> 177866 | K27: =SUM(K24:K26) -> 232887 | L27: =SUM(L24:L26) -> 280522 | M27: =SUM(M24:M26) -> 386064 | ... P27: =SUM(P24:P26) -> 574785
B29: Operating Income/(loss)
C30: North America | F30: =1166-731+350 -> 785 | G30: 360 | H30: 1425 | I30: 2361 | J30: 2837 | K30: 7267 | L30: 7033 | M30: 8651 | N30: 7271 | O30: -2847 | P30: 14877
C31: International | F31: =154-96-700 -> -642 | G31: -640 | H31: -699 | I31: -1283 | J31: -3062 | K31: -2142 | L31: -1693 | M31: 717 | N31: -924 | O31: -7746 | P31: -2656
C32: AWS (Global) | F32: =673-421+350 -> 602 | G32: 458 | H32: 1507 | I32: 3108 | J32: 4331 | K32: 7296 | L32: 9201 | M32: 13531 | N32: 18532 | O32: 22841 | P32: 24631
B33: Total Operating Income | F33: =SUM(F30:F32) -> 745 | G33: =SUM(G30:G32) -> 178 | H33: =SUM(H30:H32) -> 2233 | I33: =SUM(I30:I32) -> 4186 | J33: =SUM(J30:J32) -> 4106 | K33: =SUM(K30:K32) -> 12421 | L33: =SUM(L30:L32) -> 14541 | M33: =SUM(M30:M32) -> 22899 | ... P33: =SUM(P30:P32) -> 36852
F35: Guessed figures
C36: Composition By Geography
C37: United States | F37: =F6/F$11*100 -> 59.043411 | G37: =G6/G$11*100 -> 61.488066 | H37: =H6/H$11*100 -> 65.918734 | I37: =I6/I$11*100 -> 66.439439 | J37: =J6/J$11*100 -> 67.739759 | K37: =K6/K$11*100 -> 68.765539 | L37: =L6/L$11*100 -> 69.027028 | M37: =M6/M$11*100 -> 68.258113 | ... P37: =P6/P$11*100 -> 68.832172 | R37: =AVERAGEIF(E37:Q37,"<>0") -> 66.51203
C38: Germany | F38: =F7/F$11*100 -> 14.150056 | G38: =G7/G$11*100 -> 13.393941 | H38: =H7/H$11*100 -> 11.042371 | I38: =I7/I$11*100 -> 10.403936 | J38: =J7/J$11*100 -> 9.5302081 | K38: =K7/K$11*100 -> 8.5367582 | L38: =L7/L$11*100 -> 7.9252251 | M38: =M7/M$11*100 -> 7.6580567 | ... P38: =P7/P$11*100 -> 6.5394887 | R38: =AVERAGEIF(E38:Q38,"<>0") -> 9.4237767
C39: United Kingdom | F39: =F8/F$11*100 -> 9.7928867 | G39: =G8/G$11*100 -> 9.3731739 | H39: =H8/H$11*100 -> 8.4415827 | I39: =I8/I$11*100 -> 7.020524 | J39: =J8/J$11*100 -> 6.3935772 | K39: =K8/K$11*100 -> 6.236501 | L39: =L8/L$11*100 -> 6.2479948 | M39: =M8/M$11*100 -> 6.8597435 | ... P39: =P8/P$11*100 -> 5.8440982
C40: Japan | F40: =F9/F$11*100 -> 10.260302 | G40: =G9/G$11*100 -> 8.8910864 | H40: =H9/H$11*100 -> 7.7229314 | I40: =I9/I$11*100 -> 7.9397295 | J40: =J9/J$11*100 -> 6.6943654 | K40: =K9/K$11*100 -> 5.938073 | L40: =L9/L$11*100 -> 5.7043654 | M40: =M9/M$11*100 -> 5.2998985 | ... P40: =P9/P$11*100 -> 4.5237785 | R40: =AVERAGEIF(E40:Q40,"<>0") -> 6.6028703
C41: Rest of World | F41: =F10/F$11*100 -> 6.7533444 | G41: =G10/G$11*100 -> 6.8537331 | H41: =H10/H$11*100 -> 6.8743809 | I41: =I10/I$11*100 -> 8.1963717 | J41: =J10/J$11*100 -> 9.6420901 | K41: =K10/K$11*100 -> 10.523129 | L41: =L10/L$11*100 -> 11.095386 | M41: =M10/M$11*100 -> 11.924189 | ... P41: =P10/P$11*100 -> 14.260463 | R41: =AVERAGEIF(E41:Q41,"<>0") -> 10.292774
F42: =SUM(F37:F41) -> 100 | G42: =SUM(G37:G41) -> 100 | H42: =SUM(H37:H41) -> 100 | I42: =SUM(I37:I41) -> 100 | J42: =SUM(J37:J41) -> 100 | K42: =SUM(K37:K41) -> 100 | L42: =SUM(L37:L41) -> 100 | M42: =SUM(M37:M41) -> 100 | ... P42: =SUM(P37:P41) -> 100
C44: Composition By Specific Segments
C45: Online Stores | F45: =F14/F$21*100 -> 94.716059 | G45: =G14/G$21*100 -> 76.99128 | H45: =H14/H$21*100 -> 71.830552 | I45: =I14/I$21*100 -> 67.235103 | J45: =J14/J$21*100 -> 60.918894 | K45: =K14/K$21*100 -> 52.809732 | L45: =L14/L$21*100 -> 50.351488 | M45: =M14/M$21*100 -> 51.117431 | ... P45: =P14/P$21*100 -> 40.340649 | R45: =AVERAGEIF(E45:Q45,"<>0") -> 59.671167
C46: Physical Stores | F46: =F15/F$21*100 -> 0 | G46: =G15/G$21*100 -> 0 | H46: =H15/H$21*100 -> 0 | I46: =I15/I$21*100 -> 0 | J46: =J15/J$21*100 -> 3.2597573 | K46: =K15/K$21*100 -> 7.3958615 | L46: =L15/L$21*100 -> 6.1285746 | M46: =M15/M$21*100 -> 4.2031891 | ... P46: =P15/P$21*100 -> 3.4847813 | R46: =AVERAGEIF(E46:Q46,"<>0") -> 4.5422772
...

Sheet Sharpe, Sortino
B3: AMZN Monthly Price Changes (5 years) | L3: United States 10-Year Bond Yield
B4: https://www.investing.com/equities/amazon-com-inc-historical-data | L4: https://www.investing.com/rates-bonds/u.s.-10-year-bond-yield-historical-data
B5: Jan'19 - Dec'23 | L5: Risk free rate average | O5: =[1]Sheet1!$E$6 -> 0.0246945 | S5: TEST (Manual calculation of Monthly Std Dev of Excess Returns - 5 Years)
F7: [1] | G7: [2] | H7: [1] - [2] | J7: [1] - [2] | S7: Sharpe | X7: Sortino
B8: Date | C8: Price | D8: Change % | F8: Change | G8: Monthly Risk free rate | H8: Monthly Excess returns | J8: Monthly Excess negative returns | S8: Average Monthly Excess Returns | U8: Difference Squared | V8: Monthly Std Dev of excess returns (σ) | X8: Average Monthly Excess Negative Returns | Y8: Difference Squared | Z8: Monthly Std Dev of excess returns (σ)
A9: 1 | B9: 45261 | C9: 151.94 | D9: 0.04 | F9: =D9 -> 0.04 | G9: =O$5/12 -> 0.002057875 | H9: =F9-G9 -> 0.037942125 | J9: =IF(H9<0,H9,"") | L9: Sharpe Ratio | O9: 1 Year | P9: 3 Years | Q9: 5 Years | S9: =AVERAGE(H9:H68) -> 0.014112125 | T9: 1 | U9: =(H9-S$9)^2 -> 0.0005678689 | V9: =(U70/T68)^(1/2) -> 0.094612146 | X9: =AVERAGE(J9:J68) -> -0.067606023 | Y9: =IF(J9="","",(J9-X$9)^2) | Z9: =(Y70/(COUNT(Y9:Y69)-1))^(1/2) -> 0.048378407
A10: 2 | B10: 45231 | C10: 146.09 | D10: 0.0977 | F10: =D10 -> 0.0977 | G10: =O$5/12 -> 0.002057875 | H10: =F10-G10 -> 0.095642125 | J10: =IF(H10<0,H10,"") | T10: 2 | U10: =(H10-S$9)^2 -> 0.0066471409 | Y10: =IF(J10="","",(J10-X$9)^2)
A11: 3 | B11: 45200 | C11: 133.09 | D11: 0.047 | F11: =D11 -> 0.047 | G11: =O$5/12 -> 0.002057875 | H11: =F11-G11 -> 0.044942125 | J11: =IF(H11<0,H11,"") | L11: Monthly Std Dev of excess returns (σ) | O11: =STDEV.P(H9:H20) -> 0.08294789 | P11: =STDEV.P(H9:H44) -> 0.099570071 | Q11: =STDEV.P(H9:H68) -> 0.094612146 | T11: 3 | U11: =(H11-S$9)^2 -> 0.0009504889 | Y11: =IF(J11="","",(J11-X$9)^2)
A12: 4 | B12: 45170 | C12: 127.12 | D12: -0.0789 | F12: =D12 -> -0.0789 | G12: =O$5/12 -> 0.002057875 | H12: =F12-G12 -> -0.080957875 | J12: =IF(H12<0,H12,"") -> -0.080957875 | L12: Monthly Portfolio return (Rp) | O12: =(1+O19)^(1/12)-1 -> 0.032818302 | P12: =(1+P19)^(1/12)-1 -> -0.0014884394 | Q12: =(1+Q19)^(1/12)-1 -> 0.0095425143 | T12: 4 | U12: =(H12-S$9)^2 -> 0.0090383049 | Y12: =IF(J12="","",(J12-X$9)^2) -> 0.00017827195
A13: 5 | B13: 45139 | C13: 138.01 | D13: 0.0324 | F13: =D13 -> 0.0324 | G13: =O$5/12 -> 0.002057875 | H13: =F13-G13 -> 0.030342125 | J13: =IF(H13<0,H13,"") | L13: Monthly Risk-free return - US 10Yr Yield (Rf) | O13: =O20/12 -> 0.002057875 | P13: =P20/12 -> 0.002057875 | Q13: =Q20/12 -> 0.002057875 | T13: 5 | U13: =(H13-S$9)^2 -> 0.0002634129 | Y13: =IF(J13="","",(J13-X$9)^2)
A14: 6 | B14: 45108 | C14: 133.68 | D14: 0.0255 | F14: =D14 -> 0.0255 | G14: =O$5/12 -> 0.002057875 | H14: =F14-G14 -> 0.023442125 | J14: =IF(H14<0,H14,"") | L14: Excess return (Rp - Rf) | O14: =O12-O13 -> 0.030760427 | P14: =P12-P13 -> -0.0035463144 | Q14: =Q12-Q13 -> 0.0074846393 | T14: 6 | U14: =(H14-S$9)^2 -> 8.70489e-05 | Y14: =IF(J14="","",(J14-X$9)^2)
A15: 7 | B15: 45078 | C15: 130.36 | D15: 0.0811 | F15: =D15 -> 0.0811 | G15: =O$5/12 -> 0.002057875 | H15: =F15-G15 -> 0.079042125 | J15: =IF(H15<0,H15,"") | T15: 7 | U15: =(H15-S$9)^2 -> 0.0042159049 | Y15: =IF(J15="","",(J15-X$9)^2)
A16: 8 | B16: 45047 | C16: 120.58 | D16: 0.1435 | F16: =D16 -> 0.1435 | G16: =O$5/12 -> 0.002057875 | H16: =F16-G16 -> 0.14144213 | J16: =IF(H16<0,H16,"") | L16: Monthly Sharpe Ratio ( [Rp - Rf] / σ ) | O16: =O14/O11 -> 0.37084038 | P16: =P14/P11 -> -0.035616268 | Q16: =Q14/Q11 -> 0.079108652 | T16: 8 | U16: =(H16-S$9)^2 -> 0.016212929 | Y16: =IF(J16="","",(J16-X$9)^2)
A17: 9 | B17: 45017 | C17: 105.45 | D17: 0.0209 | F17: =D17 -> 0.0209 | G17: =O$5/12 -> 0.002057875 | H17: =F17-G17 -> 0.018842125 | J17: =IF(H17<0,H17,"") | T17: 9 | U17: =(H17-S$9)^2 -> 2.23729e-05 | Y17: =IF(J17="","",(J17-X$9)^2)
A18: 10 | B18: 44986 | C18: 103.29 | D18: 0.0961 | F18: =D18 -> 0.0961 | G18: =O$5/12 -> 0.002057875 | H18: =F18-G18 -> 0.094042125 | J18: =IF(H18<0,H18,"") | L18: Annualized Std Dev of excess returns (σ) | O18: =O11*12^(1/2) -> 0.28733992 | P18: =P11*12^(1/2) -> 0.34492084 | Q18: =Q11*12^(1/2) -> 0.32774609 | T18: 10 | U18: =(H18-S$9)^2 -> 0.0063888049 | Y18: =IF(J18="","",(J18-X$9)^2)
A19: 11 | B19: 44958 | C19: 94.23 | D19: -0.0863 | F19: =D19 -> -0.0863 | G19: =O$5/12 -> 0.002057875 | H19: =F19-G19 -> -0.088357875 | J19: =IF(H19<0,H19,"") -> -0.088357875 | L19: Annualized Portfolio return (Rp) | O19: =($C$9/$C$20)^(1/($A$20/12))-1 -> 0.47328614 | P19: =($C$9/$C$44)^(1/($A$44/12))-1 -> -0.017715776 | Q19: =($C$9/$C$68)^(1/($A$68/12))-1 -> 0.12071544 | T19: 11 | U19: =(H19-S$9)^2 -> 0.010500101 | Y19: =IF(J19="","",(J19-X$9)^2) -> 0.00043063936
A20: 12 | B20: 44927 | C20: 103.13 | D20: 0.2277 | F20: =D20 -> 0.2277 | G20: =O$5/12 -> 0.002057875 | H20: =F20-G20 -> 0.22564212 | J20: =IF(H20<0,H20,"") | L20: Annualized Risk-free return - US 10Yr Yield (Rf) | O20: =$O$5 -> 0.0246945 | P20: =$O$5 -> 0.0246945 | Q20: =$O$5 -> 0.0246945 | T20: 12 | U20: =(H20-S$9)^2 -> 0.044744941 | Y20: =IF(J20="","",(J20-X$9)^2)
A21: 13 | B21: 44896 | C21: 84 | D21: -0.1299 | F21: =D21 -> -0.1299 | G21: =O$5/12 -> 0.002057875 | H21: =F21-G21 -> -0.13195788 | J21: =IF(H21<0,H21,"") -> -0.13195788 | L21: Excess return (Rp - Rf) | O21: =O19-O20 -> 0.44859164 | P21: =P19-P20 -> -0.042410276 | Q21: =Q19-Q20 -> 0.096020938 | T21: 13 | U21: =(H21-S$9)^2 -> 0.021336445 | Y21: =IF(J21="","",(J21-X$9)^2) -> 0.0041411608
A22: 14 | B22: 44866 | C22: 96.54 | D22: -0.0576 | F22: =D22 -> -0.0576 | G22: =O$5/12 -> 0.002057875 | H22: =F22-G22 -> -0.059657875 | J22: =IF(H22<0,H22,"") -> -0.059657875 | T22: 14 | U22: =(H22-S$9)^2 -> 0.0054420129 | Y22: =IF(J22="","",(J22-X$9)^2) -> 6.3173059e-05
A23: 15 | B23: 44835 | C23: 102.44 | D23: -0.0935 | F23: =D23 -> -0.0935 | G23: =O$5/12 -> 0.002057875 | H23: =F23-G23 -> -0.095557875 | J23: =IF(H23<0,H23,"") -> -0.095557875 | L23: Annualized Sharpe Ratio ( [Rp - Rf] / σ ) | O23: =O21/O18 -> 1.561188 | P23: =P21/P18 -> -0.12295655 | Q23: =Q21/Q18 -> 0.29297356 | T23: 15 | U23: =(H23-S$9)^2 -> 0.012027509 | Y23: =IF(J23="","",(J23-X$9)^2) -> 0.00078130602
A24: 16 | B24: 44805 | C24: 113 | D24: -0.1086 | F24: =D24 -> -0.1086 | G24: =O$5/12 -> 0.002057875 | H24: =F24-G24 -> -0.11065788 | J24: =IF(H24<0,H24,"") -> -0.11065788 | T24: 16 | U24: =(H24-S$9)^2 -> 0.015567553 | Y24: =IF(J24="","",(J24-X$9)^2) -> 0.0018534619
A25: 17 | B25: 44774 | C25: 126.77 | D25: -0.0606 | F25: =D25 -> -0.0606 | G25: =O$5/12 -> 0.002057875 | H25: =F25-G25 -> -0.062657875 | J25: =IF(H25<0,H25,"") -> -0.062657875 | T25: 17 | U25: =(H25-S$9)^2 -> 0.0058936329 | Y25: =IF(J25="","",(J25-X$9)^2) -> 2.448417e-05
A26: 18 | B26: 44743 | C26: 134.95 | D26: 0.2706 | F26: =D26 -> 0.2706 | G26: =O$5/12 -> 0.002057875 | H26: =F26-G26 -> 0.26854213 | J26: =IF(H26<0,H26,"") | L26: Sortino Ratio | O26: 1 Year | P26: 3 Years | Q26: 5 Years | T26: 18 | U26: =(H26-S$9)^2 -> 0.064734625 | Y26: =IF(J26="","",(J26-X$9)^2)
A27: 19 | B27: 44713 | C27: 106.21 | D27: -0.1165 | F27: =D27 -> -0.1165 | G27: =O$5/12 -> 0.002057875 | H27: =F27-G27 -> -0.11855787 | J27: =IF(H27<0,H27,"") -> -0.11855787 | T27: 19 | U27: =(H27-S$9)^2 -> 0.017601329 | Y27: =IF(J27="","",(J27-X$9)^2) -> 0.0025960912
A28: 20 | B28: 44682 | C28: 120.21 | D28: -0.0328 | F28: =D28 -> -0.0328 | G28: =O$5/12 -> 0.002057875 | H28: =F28-G28 -> -0.034857875 | J28: =IF(H28<0,H28,"") -> -0.034857875 | L28: Monthly Std Dev of excess negative returns (σd) | O28: =_xlfn.STDEV.S(J9:J20) -> 0.0052325902 | P28: =_xlfn.STDEV.S(J9:J44) -> 0.053979823 | Q28: =_xlfn.STDEV.S(J9:J68) -> 0.048378407 | T28: 20 | U28: =(H28-S$9)^2 -> 0.0023980609 | Y28: =IF(J28="","",(J28-X$9)^2) -> 0.0010724412
A29: 21 | B29: 44652 | C29: 124.28 | D29: -0.2375 | F29: =D29 -> -0.2375 | G29: =O$5/12 -> 0.002057875 | H29: =F29-G29 -> -0.23955788 | J29: =IF(H29<0,H29,"") -> -0.23955788 | L29: Monthly Portfolio return (Rp) | O29: =(1+O36)^(1/12)-1 -> 0.032818302 | P29: =(1+P36)^(1/12)-1 -> -0.0014884394 | Q29: =(1+Q36)^(1/12)-1 -> 0.0095425143 | T29: 21 | U29: =(H29-S$9)^2 -> 0.064348469 | Y29: =IF(J29="","",(J29-X$9)^2) -> 0.029567439
A30: 22 | B30: 44621 | C30: 163 | D30: 0.0614 | F30: =D30 -> 0.0614 | G30: =O$5/12 -> 0.002057875 | H30: =F30-G30 -> 0.059342125 | J30: =IF(H30<0,H30,"") | L30: Monthly Risk-free return - US 10Yr Yield (Rf) | O30: =O37/12 -> 0.002057875 | P30: =P37/12 -> 0.002057875 | Q30: =Q37/12 -> 0.002057875 | T30: 22 | U30: =(H30-S$9)^2 -> 0.0020457529 | Y30: =IF(J30="","",(J30-X$9)^2)
A31: 23 | B31: 44593 | C31: 153.56 | D31: 0.0267 | F31: =D31 -> 0.0267 | G31: =O$5/12 -> 0.002057875 | H31: =F31-G31 -> 0.024642125 | J31: =IF(H31<0,H31,"") | L31: Excess return (Rp - Rf) | O31: =O29-O30 -> 0.030760427 | P31: =P29-P30 -> -0.0035463144 | Q31: =Q29-Q30 -> 0.0074846393 | T31: 23 | U31: =(H31-S$9)^2 -> 0.0001108809 | Y31: =IF(J31="","",(J31-X$9)^2)
A32: 24 | B32: 44562 | C32: 149.57 | D32: -0.1028 | F32: =D32 -> -0.1028 | G32: =O$5/12 -> 0.002057875 | H32: =F32-G32 -> -0.10485788 | J32: =IF(H32<0,H32,"") -> -0.10485788 | T32: 24 | U32: =(H32-S$9)^2 -> 0.014153861 | Y32: =IF(J32="","",(J32-X$9)^2) -> 0.0013877005
A33: 25 | B33: 44531 | C33: 166.72 | D33: -0.0493 | F33: =D33 -> -0.0493 | G33: =O$5/12 -> 0.002057875 | H33: =F33-G33 -> -0.051357875 | J33: =IF(H33<0,H33,"") -> -0.051357875 | L33: Monthly Sortino Ratio ( [Rp - Rf] / σ ) | O33: =O31/O28 -> 5.8786234 | P33: =P31/P28 -> -0.065697035 | Q33: =Q31/Q28 -> 0.15471033 | T33: 25 | U33: =(H33-S$9)^2 -> 0.0042863209 | Y33: =IF(J33="","",(J33-X$9)^2) -> 0.00026400232
A34: 26 | B34: 44501 | C34: 175.35 | D34: 0.0399 | F34: =D34 -> 0.0399 | G34: =O$5/12 -> 0.002057875 | H34: =F34-G34 -> 0.037842125 | J34: =IF(H34<0,H34,"") | T34: 26 | U34: =(H34-S$9)^2 -> 0.0005631129 | Y34: =IF(J34="","",(J34-X$9)^2)
A35: 27 | B35: 44470 | C35: 168.62 | D35: 0.0266 | F35: =D35 -> 0.0266 | G35: =O$5/12 -> 0.002057875 | H35: =F35-G35 -> 0.024542125 | J35: =IF(H35<0,H35,"") | L35: Annualized Std Dev of excess negative returns (σ) | O35: =O28*12^(1/2) -> 0.018126224 | P35: =P28*12^(1/2) -> 0.18699159 | Q35: =Q28*12^(1/2) -> 0.16758772 | T35: 27 | U35: =(H35-S$9)^2 -> 0.0001087849 | Y35: =IF(J35="","",(J35-X$9)^2)
A36: 28 | B36: 44440 | C36: 164.25 | D36: -0.0535 | F36: =D36 -> -0.0535 | G36: =O$5/12 -> 0.002057875 | H36: =F36-G36 -> -0.055557875 | J36: =IF(H36<0,H36,"") -> -0.055557875 | L36: Annualized Portfolio return (Rp) | O36: =($C$9/$C$20)^(1/($A$20/12))-1 -> 0.47328614 | P36: =($C$9/$C$44)^(1/($A$44/12))-1 -> -0.017715776 | Q36: =($C$9/$C$68)^(1/($A$68/12))-1 -> 0.12071544 | T36: 28 | U36: =(H36-S$9)^2 -> 0.0048539089 | Y36: =IF(J36="","",(J36-X$9)^2) -> 0.00014515787
A37: 29 | B37: 44409 | C37: 173.54 | D37: 0.043 | F37: =D37 -> 0.043 | G37: =O$5/12 -> 0.002057875 | H37: =F37-G37 -> 0.040942125 | J37: =IF(H37<0,H37,"") | L37: Annualized Risk-free return - US 10Yr Yield (Rf) | O37: =$O$5 -> 0.0246945 | P37: =$O$5 -> 0.0246945 | Q37: =$O$5 -> 0.0246945 | T37: 29 | U37: =(H37-S$9)^2 -> 0.0007198489 | Y37: =IF(J37="","",(J37-X$9)^2)
A38: 30 | B38: 44378 | C38: 166.38 | D38: -0.0327 | F38: =D38 -> -0.0327 | G38: =O$5/12 -> 0.002057875 | H38: =F38-G38 -> -0.034757875 | J38: =IF(H38<0,H38,"") -> -0.034757875 | L38: Excess return (Rp - Rf) | O38: =O36-O37 -> 0.44859164 | P38: =P36-P37 -> -0.042410276 | Q38: =Q36-Q37 -> 0.096020938 | T38: 30 | U38: =(H38-S$9)^2 -> 0.0023882769 | Y38: =IF(J38="","",(J38-X$9)^2) -> 0.0010790008
A39: 31 | B39: 44348 | C39: 172.01 | D39: 0.0674 | F39: =D39 -> 0.0674 | G39: =O$5/12 -> 0.002057875 | H39: =F39-G39 -> 0.065342125 | J39: =IF(H39<0,H39,"") | T39: 31 | U39: =(H39-S$9)^2 -> 0.0026245129 | Y39: =IF(J39="","",(J39-X$9)^2)
A40: 32 | B40: 44317 | C40: 161.15 | D40: -0.0705 | F40: =D40 -> -0.0705 | G40: =O$5/12 -> 0.002057875 | H40: =F40-G40 -> -0.072557875 | J40: =IF(H40<0,H40,"") -> -0.072557875 | L40: Annualized Sortino Ratio ( [Rp - Rf] / σd ) | O40: =O38/O35 -> 24.748212 | P40: =P38/P35 -> -0.22680311 | Q40: =Q38/Q35 -> 0.57295928 | T40: 32 | U40: =(H40-S$9)^2 -> 0.0075116889 | Y40: =IF(J40="","",(J40-X$9)^2) -> 2.4520837e-05
A41: 33 | B41: 44287 | C41: 173.37 | D41: 0.1207 | F41: =D41 -> 0.1207 | G41: =O$5/12 -> 0.002057875 | H41: =F41-G41 -> 0.11864213 | J41: =IF(H41<0,H41,"") | T41: 33 | U41: =(H41-S$9)^2 -> 0.010926521 | Y41: =IF(J41="","",(J41-X$9)^2)
A42: 34 | B42: 44256 | C42: 154.7 | D42: 0.0004 | F42: =D42 -> 0.0004 | G42: =O$5/12 -> 0.002057875 | H42: =F42-G42 -> -0.001657875 | J42: =IF(H42<0,H42,"") -> -0.001657875 | T42: 34 | U42: =(H42-S$9)^2 -> 0.0002486929 | Y42: =IF(J42="","",(J42-X$9)^2) -> 0.0043491582
A43: 35 | B43: 44228 | C43: 154.65 | D43: -0.0353 | F43: =D43 -> -0.0353 | G43: =O$5/12 -> 0.002057875 | H43: =F43-G43 -> -0.037357875 | J43: =IF(H43<0,H43,"") -> -0.037357875 | T43: 35 | U43: =(H43-S$9)^2 -> 0.0026491609 | Y43: =IF(J43="","",(J43-X$9)^2) -> 0.00091495047
...
