Workbook

Sheet Overall
B2: SUMMARY
H3: Share price | K3: Profit Margins | T3: Valuations Multiples | AC3: Solvency | AL3: Efficiency | AU3: Risk
H4: CAGR | K4: GPM | N4: OM | Q4: NPM | T4: PE | W4: EPS | Z4: Dividend Yield | AC4: Debt Ratio | AF4: Debt - Equity | AI4: Debt - Revenue | AL4: IT | AO4: RT | AR4: PT | AU4: Sharpe Ratio | AX4: Sortino Ratio
B5: Base year | D5: Y/E | E5: Updated As At | F5: MC | G5: Share price at Y/E | H5: Current | I5: 3 years | J5: 5 years | K5: Current | L5: 3 years | M5: 5 years | N5: Current | O5: 3 years | P5: 5 years | Q5: Current | R5: 3 years | S5: 5 years | T5: Current | U5: 3 years | V5: 5 years | W5: Current | X5: 3 years | Y5: 5 years | Z5: Current | AA5: 3 years | AB5: 5 years | AC5: Current | AD5: 3 years | AE5: 5 years | AF5: Current | AG5: 3 years | AH5: 5 years | AI5: Current | AJ5: 3 years | AK5: 5 years | AL5: Current | AM5: 3 years | AN5: 5 years | AO5: Current | AP5: 3 years | AQ5: 5 years | AR5: Current | AS5: 3 years | AT5: 5 years | AU5: Current | AV5: 3 years | AW5: 5 years | AX5: Current | AY5: 3 years | AZ5: 5 years
B6: 2023 | D6: 31/12 | E6: 2023 | F6: =OFFSET(FS!P113,0,E$6-B$6) -> 1779945.9 | G6: =OFFSET(FS!P107,0,E$6-B$6) -> 140.93 | H6: =((OFFSET(FS!P107,0,E$6-B$6)/OFFSET(FS!P107,0,-1+E$6-B$6))^(1/1)-1)*100 -> 58.830159 | I6: =((OFFSET(FS!P107,0,E$6-B$6)/OFFSET(FS!P107,0,-2+E$6-B$6))^(1/3)-1)*100 -> -1.1711977 | J6: =((OFFSET(FS!P107,0,E$6-B$6)/OFFSET(FS!P107,0,-4+E$6-B$6))^(1/5)-1)*100 -> 16.085803 | K6: =OFFSET(FS!P82,0,0+E$6-B$6) -> 43.374952 | L6: =AVERAGE(OFFSET(FS!P82,0,-2+E$6-B$6):OFFSET(FS!P82,0,E$6-B$6)) -> 43.685236 | M6: =AVERAGE(OFFSET(FS!P82,0,-4+E$6-B$6):OFFSET(FS!P82,0,E$6-B$6)) -> 44.379358 | N6: =OFFSET(FS!P91,0,0+E$6-B$6) -> 27.42181 | O6: =AVERAGE(OFFSET(FS!P91,0,-2+E$6-B$6):OFFSET(FS!P91,0,E$6-B$6)) -> 28.145123 | P6: =AVERAGE(OFFSET(FS!P91,0,-4+E$6-B$6):OFFSET(FS!P91,0,E$6-B$6)) -> 25.633887 | Q6: =OFFSET(FS!P100,0,0+E$6-B$6) -> 24.006649 | R6: =AVERAGE(OFFSET(FS!P100,0,-2+E$6-B$6):OFFSET(FS!P100,0,E$6-B$6)) -> 24.907378 | S6: =AVERAGE(OFFSET(FS!P100,0,-4+E$6-B$6):OFFSET(FS!P100,0,E$6-B$6)) -> 23.600438 | T6: =OFFSET(FS!P109,0,0+E$6-B$6) -> 24.120142 | U6: =AVERAGE(OFFSET(FS!P109,0,-2+E$6-B$6):OFFSET(FS!P109,0,E$6-B$6)) -> 23.029281 | V6: =AVERAGE(OFFSET(FS!P109,0,-4+E$6-B$6):OFFSET(FS!P109,0,E$6-B$6)) -> 25.052164 | W6: =OFFSET(FS!P108,0,0+E$6-B$6) -> 5.8428345 | X6: =AVERAGE(OFFSET(FS!P108,0,-2+E$6-B$6):OFFSET(FS!P108,0,E$6-B$6)) -> 5.3759643 | Y6: =AVERAGE(OFFSET(FS!P108,0,-4+E$6-B$6):OFFSET(FS!P108,0,E$6-B$6)) -> 4.3208888 | Z6: 0 | AA6: 0 | AB6: 0 | AC6: =OFFSET(FS!P168,0,0+E$6-B$6) -> 0.29576383 | AD6: =AVERAGE(OFFSET(FS!P168,0,-2+E$6-B$6):OFFSET(FS!P168,0,E$6-B$6)) -> 0.29803213 | AE6: =AVERAGE(OFFSET(FS!P168,0,-4+E$6-B$6):OFFSET(FS!P168,0,E$6-B$6)) -> 0.29354156 | AF6: =OFFSET(FS!P169,0,0+E$6-B$6) -> 0.41997819 | AG6: =AVERAGE(OFFSET(FS!P169,0,-2+E$6-B$6):OFFSET(FS!P169,0,E$6-B$6)) -> 0.42457439 | AH6: =AVERAGE(OFFSET(FS!P169,0,-4+E$6-B$6):OFFSET(FS!P169,0,E$6-B$6)) -> 0.41591705 | AI6: =OFFSET(FS!P170,0,0+E$6-B$6) -> 0.38716761 | AJ6: =AVERAGE(OFFSET(FS!P170,0,-2+E$6-B$6):OFFSET(FS!P170,0,E$6-B$6)) -> 0.39691473 | AK6: =AVERAGE(OFFSET(FS!P170,0,-4+E$6-B$6):OFFSET(FS!P170,0,E$6-B$6)) -> 0.43652917 | AL6: 0 | AM6: 0 | AN6: 0 | AO6: =OFFSET(FS!P173,0,0+E$6-B$6) -> 6.4088483 | AP6: =AVERAGE(OFFSET(FS!P173,0,-2+E$6-B$6):OFFSET(FS!P173,0,E$6-B$6)) -> 6.6631383 | AQ6: =AVERAGE(OFFSET(FS!P173,0,-4+E$6-B$6):OFFSET(FS!P173,0,E$6-B$6)) -> 6.4563301 | AR6: =OFFSET(FS!P174,0,0+E$6-B$6) -> 17.794208 | AS6: =AVERAGE(OFFSET(FS!P174,0,-2+E$6-B$6):OFFSET(FS!P174,0,E$6-B$6)) -> 20.26043 | AT6: =AVERAGE(OFFSET(FS!P174,0,-4+E$6-B$6):OFFSET(FS!P174,0,E$6-B$6)) -> 17.774079 | AU6: ='Sharpe, Sortino'!O23 -> 1.4517894 | AV6: ='Sharpe, Sortino'!P23 -> 0.4549862 | AW6: ='Sharpe, Sortino'!Q23 -> 0.66756019 | AX6: ='Sharpe, Sortino'!O40 -> 3.458234 | AY6: ='Sharpe, Sortino'!P40 -> 0.74493281 | AZ6: ='Sharpe, Sortino'!Q40 -> 1.0791802

Sheet FS
F1: < Figures are in millions >
F2: Y/E 31/12 | U2: Annualized | AM2: 25/04/23 | AN2: 26/07/23 | AO2: 25/10/23 | AP2: 30/01/24 | AQ2: 25/04/24 | AR2: 23/07/24
F3: 2013 | G3: 2014 | H3: 2015 | I3: 2016 | J3: 2017 | K3: 2018 | L3: 2019 | M3: 2020 | N3: 2021 | O3: 2022 | P3: 2023 | R3: Average | S3: Median | T3: CAGR | U3: Std Dev | W3: Q1'19 | X3: Q2'19 | Y3: Q3'19 | Z3: Q4'19 | AA3: Q1'20 | AB3: Q2'20 | AC3: Q3'20 | AD3: Q4'20 | AE3: Q1'21 | AF3: Q2'21 | AG3: Q3'21 | AH3: Q4'21 | AI3: Q1'22 | AJ3: Q2'22 | AK3: Q3'22 | AL3: Q4'22 | AM3: Q1'23 | AN3: Q2'23 | AO3: Q3'23 | AP3: Q4'23 | AQ3: Q1'24 | AR3: Q2'24
B5: Revenue By Geography
C6: United States | F6: 25587 | G6: 29482 | H6: 34810 | I6: 42781 | J6: 52449 | K6: 63269 | L6: 74843 | M6: 85014 | N6: 117854 | O6: 134814 | P6: 146286 | AA6: 18870 | AB6: 17999 | AC6: 21442 | AD6: 26703 | AE6: 25032 | AF6: 28208 | AG6: 29824 | AH6: 34790 | AI6: 31733 | AJ6: 32727 | AK6: 33372 | AL6: 36982 | AM6: 32864 | AN6: 35073 | AO6: 36354 | AP6: 41995 | AQ6: 38737 | AR6: 41196
C7: Europe, Middle East & Africa (EMEA) | F7: =5604+24835 -> 30439 | G7: =6480+29867 -> 36347 | H7: 29181 | I7: 31116 | J7: 36236 | K7: 44739 | L7: 50645 | M7: 55370 | N7: 79107 | O7: 82062 | P7: 91038 | AA7: 12845 | AB7: 11363 | AC7: 13924 | AD7: 17238 | AE7: 17031 | AF7: 19084 | AG7: 19839 | AH7: 23153 | AI7: 20317 | AJ7: 20533 | AK7: 19450 | AL7: 21762 | AM7: 21078 | AN7: 22289 | AO7: 22661 | AP7: 25010 | AQ7: 23788 | AR7: 24683
C8: Asia-Pacific (APAC) | H8: 10640 | I8: 12166 | J8: 16192 | K8: 21341 | L8: 26928 | M8: 32550 | N8: 46123 | O8: 47024 | P8: 51514 | AA8: 7238 | AB8: 6945 | AC8: 8458 | AD8: 9909 | AE8: 10455 | AF8: 11231 | AG8: 11705 | AH8: 12732 | AI8: 11841 | AJ8: 11710 | AK8: 11494 | AL8: 11979 | AM8: 11681 | AN8: 12728 | AO8: 13126 | AP8: 13979 | AQ8: 13289 | AR8: 13823
C9: Canada & Latin America (Other Americas) | H9: 4548 | I9: 4943 | J9: 6147 | K9: 7608 | L9: 8986 | M9: 9417 | N9: 14404 | O9: 16976 | P9: 18320 | AA9: 2157 | AB9: 1839 | AC9: 2371 | AD9: 3050 | AE9: 2905 | AF9: 3364 | AG9: 3688 | AH9: 4447 | AI9: 3842 | AJ9: 4340 | AK9: 4138 | AL9: 4656 | AM9: 4080 | AN9: 4511 | AO9: 4553 | AP9: 5176 | AQ9: 4653 | AR9: 4938
C10: Hedging gains/(losses) | F10: =-(67-63+535-32) -> -507 | G10: =-(-3-169) -> 172 | H10: =-(3802-989+1076-323+712-88) -> -4190 | I10: =-(1291-479-362-31+344-29) -> -734 | J10: -169 | K10: -138 | L10: 455 | M10: 176 | N10: 149 | O10: 1960 | P10: 236 | AA10: 49 | AB10: 151 | AC10: -22 | AD10: -2 | AE10: -109 | AF10: -7 | AG10: 62 | AH10: 203 | AI10: 278 | AJ10: 375 | AK10: 638 | AL10: 669 | AM10: 84 | AN10: 3 | AO10: -1 | AP10: 150 | AQ10: 72 | AR10: 102
B11: Total Revenues | F11: =SUM(F6:F10) -> 55519 | G11: =SUM(G6:G10) -> 66001 | H11: =SUM(H6:H10) -> 74989 | I11: =SUM(I6:I10) -> 90272 | J11: =SUM(J6:J10) -> 110855 | K11: =SUM(K6:K10) -> 136819 | L11: =SUM(L6:L10) -> 161857 | M11: =SUM(M6:M10) -> 182527 | ... P11: =SUM(P6:P10) -> 307394 | W11: =SUM(W6:W10) -> 0 | X11: =SUM(X6:X10) -> 0 | Y11: =SUM(Y6:Y10) -> 0 | Z11: =SUM(Z6:Z10) -> 0 | AA11: =SUM(AA6:AA10) -> 41159 | AB11: =SUM(AB6:AB10) -> 38297 | AC11: =SUM(AC6:AC10) -> 46173 | AD11: =SUM(AD6:AD10) -> 56898 | ... AR11: =SUM(AR6:AR10) -> 84742
B13: Revenue Breakdown
C14: Advertising
D15: Search & Other | F15: 37422 | G15: 45085 | H15: 52357 | I15: 63785 | J15: 69811 | K15: 85296 | L15: 98115 | M15: 104062 | N15: 148951 | O15: 162450 | P15: 175033 | W15: 22547 | X15: 23642 | Y15: 24741 | Z15: 27185 | AA15: 24502 | AB15: 21319 | AC15: 26338 | AD15: 31903 | AE15: 31879 | AF15: 35845 | AG15: 37926 | AH15: 43301 | AI15: 39618 | AJ15: 40689 | AK15: 39539 | AL15: 42604 | AM15: 40359 | AN15: 42628 | AO15: 44026 | AP15: 48020 | AQ15: 46156 | AR15: 48509
D16: Youtube ads | F16: 13650 | G16: 14539 | H16: 15033 | I16: 15598 | J16: 8150 | K16: 11155 | L16: 15149 | M16: 19772 | N16: 28845 | O16: 29243 | P16: 31510 | W16: 3025 | X16: 3603 | Y16: 3804 | Z16: 4717 | AA16: 4038 | AB16: 3812 | AC16: 5037 | AD16: 6885 | AE16: 6005 | AF16: 7002 | AG16: 7205 | AH16: 8633 | AI16: 6869 | AJ16: 7340 | AK16: 7071 | AL16: 7963 | AM16: 6693 | AN16: 7665 | AO16: 7952 | AP16: 9200 | AQ16: 8090 | AR16: 8663
D17: Google network | J17: 17616 | K17: 20010 | L17: 21547 | M17: 23090 | N17: 31701 | O17: 32780 | P17: 31312 | W17: 5015 | X17: 5249 | Y17: 5251 | Z17: 6032 | AA17: 5223 | AB17: 4736 | AC17: 5720 | AD17: 7411 | AE17: 6800 | AF17: 7597 | AG17: 7999 | AH17: 9305 | AI17: 8174 | AJ17: 8259 | AK17: 7872 | AL17: 8475 | AM17: 7496 | AN17: 7850 | AO17: 7669 | AP17: 8297 | AQ17: 7413 | AR17: 7444
F18: =SUM(F15:F17) -> 51072 | G18: =SUM(G15:G17) -> 59624 | H18: =SUM(H15:H17) -> 67390 | I18: =SUM(I15:I17) -> 79383 | J18: =SUM(J15:J17) -> 95577 | K18: =SUM(K15:K17) -> 116461 | L18: =SUM(L15:L17) -> 134811 | M18: =SUM(M15:M17) -> 146924 | ... P18: =SUM(P15:P17) -> 237855 | W18: =SUM(W15:W17) -> 30587 | X18: =SUM(X15:X17) -> 32494 | Y18: =SUM(Y15:Y17) -> 33796 | Z18: =SUM(Z15:Z17) -> 37934 | AA18: =SUM(AA15:AA17) -> 33763 | AB18: =SUM(AB15:AB17) -> 29867 | AC18: =SUM(AC15:AC17) -> 37095 | AD18: =SUM(AD15:AD17) -> 46199 | ... AR18: =SUM(AR15:AR17) -> 64616
C19: Google subscriptions, platform & devices | F19: 4435 | G19: 6050 | H19: 7154 | I19: 10601 | J19: 10914 | K19: 14063 | L19: 17014 | M19: 21711 | N19: 28032 | O19: 29055 | P19: 34688 | W19: 3620 | X19: 4080 | Y19: 4050 | Z19: 5264 | AA19: 4435 | AB19: 5124 | AC19: 5478 | AD19: 6674 | AE19: 6494 | AF19: 6623 | AG19: 6754 | AH19: 8161 | AI19: 6811 | AJ19: 6553 | AK19: 6895 | AL19: 8796 | AM19: 7413 | AN19: 8142 | AO19: 8339 | AP19: 10794 | AQ19: 8739 | AR19: 9312
C20: Google Services (Total) | F20: =SUM(F18:F19) -> 55507 | G20: =SUM(G18:G19) -> 65674 | H20: =SUM(H18:H19) -> 74544 | I20: =SUM(I18:I19) -> 89984 | J20: =SUM(J18:J19) -> 106491 | K20: =SUM(K18:K19) -> 130524 | L20: =SUM(L18:L19) -> 151825 | M20: =SUM(M18:M19) -> 168635 | ... P20: =SUM(P18:P19) -> 272543 | W20: =SUM(W18:W19) -> 34207 | X20: =SUM(X18:X19) -> 36574 | Y20: =SUM(Y18:Y19) -> 37846 | Z20: =SUM(Z18:Z19) -> 43198 | AA20: =SUM(AA18:AA19) -> 38198 | AB20: =SUM(AB18:AB19) -> 34991 | AC20: =SUM(AC18:AC19) -> 42573 | AD20: =SUM(AD18:AD19) -> 52873 | ... AR20: =SUM(AR18:AR19) -> 73928
C21: Google Cloud | F21: 0 | G21: 0 | H21: 0 | I21: 0 | J21: 4056 | K21: 5838 | L21: 8918 | M21: 13059 | N21: 19206 | O21: 26280 | P21: 33088 | W21: 1825 | X21: 2100 | Y21: 2379 | Z21: 2614 | AA21: 2777 | AB21: 3007 | AC21: 3444 | AD21: 3831 | AE21: 4047 | AF21: 4628 | AG21: 4990 | AH21: 5541 | AI21: 5821 | AJ21: 6276 | AK21: 6868 | AL21: 7315 | AM21: 7454 | AN21: 8031 | AO21: 8411 | AP21: 9192 | AQ21: 9574 | AR21: 10347
C22: Other Bets | F22: 12 | G22: 327 | H22: 445 | I22: 288 | J22: 477 | K22: 595 | L22: 659 | M22: 657 | N22: 753 | O22: 1068 | P22: 1527 | W22: 170 | X22: 162 | Y22: 155 | Z22: 172 | AA22: 135 | AB22: 148 | AC22: 178 | AD22: 196 | AE22: 198 | AF22: 192 | AG22: 182 | AH22: 181 | AI22: 440 | AJ22: 193 | AK22: 209 | AL22: 226 | AM22: 288 | AN22: 285 | AO22: 297 | AP22: 657 | AQ22: 495 | AR22: 365
C23: Hedging gains/(losses) | F23: 0 | G23: 0 | H23: 0 | I23: 0 | J23: -169 | K23: -138 | L23: 455 | M23: 176 | N23: 149 | O23: 1960 | P23: 236 | W23: 137 | X23: 108 | Y23: 119 | Z23: 91 | AA23: 49 | AB23: 151 | AC23: -22 | AD23: -2 | AE23: -109 | AF23: -7 | AG23: 62 | AH23: 203 | AI23: 278 | AJ23: 375 | AK23: 638 | AL23: 669 | AM23: 84 | AN23: 3 | AO23: -1 | AP23: 150 | AQ23: 72 | AR23: 102
B24: Total Revenues | F24: =SUM(F20:F23) -> 55519 | G24: =SUM(G20:G23) -> 66001 | H24: =SUM(H20:H23) -> 74989 | I24: =SUM(I20:I23) -> 90272 | J24: =SUM(J20:J23) -> 110855 | K24: =SUM(K20:K23) -> 136819 | L24: =SUM(L20:L23) -> 161857 | M24: =SUM(M20:M23) -> 182527 | ... P24: =SUM(P20:P23) -> 307394 | W24: =SUM(W20:W23) -> 36339 | X24: =SUM(X20:X23) -> 38944 | Y24: =SUM(Y20:Y23) -> 40499 | Z24: =SUM(Z20:Z23) -> 46075 | AA24: =SUM(AA20:AA23) -> 41159 | AB24: =SUM(AB20:AB23) -> 38297 | AC24: =SUM(AC20:AC23) -> 46173 | AD24: =SUM(AD20:AD23) -> 56898 | ... AR24: =SUM(AR20:AR23) -> 84742
B26: Total traffic acquisition cost (TAC) | F26: 12258 | G26: 13497 | H26: 14343 | I26: 16793 | J26: 21672 | K26: 26726 | L26: 30089 | M26: 32778 | N26: 45566 | O26: 48955 | P26: 50886 | W26: 3860 | X26: 7238 | Y26: 7490 | Z26: 8501 | AA26: 7452 | AB26: 6694 | AC26: 8166 | AD26: 10466 | AE26: 9712 | AF26: 10929 | AG26: 11498 | AH26: 13427 | AI26: 11990 | AJ26: 12214 | AK26: 11826 | AL26: 12925 | AM26: 11721 | AN26: 12537 | AO26: 12642 | AP26: 13986 | AQ26: 12946 | AR26: 13387
B27: Number of employees (headcount) | F27: 43862 | G27: 53600 | H27: 61814 | I27: 72053 | J27: 80110 | K27: 98771 | L27: 118899 | M27: 135301 | N27: 156500 | O27: 190234 | P27: 182502 | W27: 103459 | X27: 107646 | Y27: 114096 | Z27: 118899 | AA27: 123048 | AB27: 127498 | AC27: 132121 | AD27: 135301 | AE27: 139995 | AF27: 144056 | AG27: 150028 | AH27: 156500 | AI27: 163906 | AJ27: 174014 | AK27: 186779 | AL27: 190234 | AM27: 190711 | AN27: 181798 | AO27: 182381 | AP27: 182502 | AQ27: 180895 | AR27: 179582
B29: Operating Income/(loss) Breakdown
C30: Google Services | F30: 16260 | G30: 18965 | H30: 23319 | I30: 27055 | J30: 32287 | K30: 36517 | L30: 48999 | M30: 54606 | N30: 88132 | O30: 82699 | P30: 95858 | W30: 9188 | X30: 10280 | Y30: 10746 | Z30: 13488 | AA30: 11548 | AB30: 9539 | AC30: 14453 | AD30: 19066 | AE30: 19546 | AF30: 22343 | AG30: 23973 | AH30: 25993 | AI30: 21973 | AJ30: 21621 | AK30: 18883 | AL30: 20222 | AM30: 21737 | AN30: 23454 | AO30: 23937 | AP30: 26730 | AQ30: 27897 | AR30: 29674
C31: Google Cloud | L31: -4645 | M31: -5607 | N31: -2282 | O31: -1922 | P31: 1716 | Z31: -1194 | AA31: -1730 | AB31: -1426 | AC31: -1208 | AD31: -1243 | AE31: -974 | AF31: -591 | AG31: -644 | AH31: -890 | AI31: -706 | AJ31: -590 | AK31: -440 | AL31: -186 | AM31: 191 | AN31: 395 | AO31: 266 | AP31: 864 | AQ31: 900 | AR31: 1172
C32: Other Bets | F32: -527 | G32: -1893 | H32: -3456 | I32: -2741 | J32: -2734 | K32: -3358 | L32: -4824 | M32: -4476 | N32: -4051 | O32: -4636 | P32: -4095 | W32: -868 | X32: -989 | Y32: -941 | Z32: -2026 | AA32: -1121 | AB32: -1116 | AC32: -1103 | AD32: -1136 | AE32: -1145 | AF32: -1398 | AG32: -1288 | AH32: -1450 | AI32: -835 | AJ32: -1339 | AK32: -1225 | AL32: -1237 | AM32: -1225 | AN32: -813 | AO32: -1194 | AP32: -863 | AQ32: -1020 | AR32: -1134
C33: Alphabet-level activities | F33: -330 | G33: -576 | H33: -503 | I33: -598 | J33: -3407 | K33: -6838 | L33: -5299 | M33: -3299 | N33: -3085 | O33: -1299 | P33: -9186 | W33: -1712 | X33: -111 | Y33: -628 | Z33: -1002 | AA33: -720 | AB33: -614 | AC33: -929 | AD33: -1036 | AE33: -990 | AF33: -993 | AG33: -1010 | AH33: -1768 | AI33: -338 | AJ33: -239 | AK33: -83 | AL33: -639 | AM33: -3288 | AN33: -1198 | AO33: -1666 | AP33: -3034 | AQ33: -2305 | AR33: -2287
B34: Total Operating Income | F34: =SUM(F30:F33) -> 15403 | G34: =SUM(G30:G33) -> 16496 | H34: =SUM(H30:H33) -> 19360 | I34: =SUM(I30:I33) -> 23716 | J34: =SUM(J30:J33) -> 26146 | K34: =SUM(K30:K33) -> 26321 | L34: =SUM(L30:L33) -> 34231 | M34: =SUM(M30:M33) -> 41224 | ... P34: =SUM(P30:P33) -> 84293 | W34: =SUM(W30:W33) -> 6608 | X34: =SUM(X30:X33) -> 9180 | Y34: =SUM(Y30:Y33) -> 9177 | Z34: =SUM(Z30:Z33) -> 9266 | AA34: =SUM(AA30:AA33) -> 7977 | AB34: =SUM(AB30:AB33) -> 6383 | AC34: =SUM(AC30:AC33) -> 11213 | AD34: =SUM(AD30:AD33) -> 15651 | ... AR34: =SUM(AR30:AR33) -> 27425
C37: Composition By Geography
C38: United States | F38: =F6/F$11*100 -> 46.086925 | G38: =G6/G$11*100 -> 44.66902 | H38: =H6/H$11*100 -> 46.420142 | I38: =I6/I$11*100 -> 47.391218 | J38: =J6/J$11*100 -> 47.313157 | K38: =K6/K$11*100 -> 46.242846 | L38: =L6/L$11*100 -> 46.2402 | M38: =M6/M$11*100 -> 46.576123 | ... P38: =P6/P$11*100 -> 47.589088 | R38: =AVERAGEIF(E38:Q38,"<>0") -> 46.539818
C39: Europe, Middle East & Africa (EMEA) | F39: =F7/F$11*100 -> 54.826276 | G39: =G7/G$11*100 -> 55.070378 | H39: =H7/H$11*100 -> 38.913707 | I39: =I7/I$11*100 -> 34.46916 | J39: =J7/J$11*100 -> 32.687745 | K39: =K7/K$11*100 -> 32.699406 | L39: =L7/L$11*100 -> 31.289966 | M39: =M7/M$11*100 -> 30.335238 | ... P39: =P7/P$11*100 -> 29.616063 | R39: =AVERAGEIF(E39:Q39,"<>0") -> 36.329705
C40: Asia-Pacific (APAC) | F40: =F8/F$11*100 -> 0 | G40: =G8/G$11*100 -> 0 | H40: =H8/H$11*100 -> 14.188748 | I40: =I8/I$11*100 -> 13.477047 | J40: =J8/J$11*100 -> 14.606468 | K40: =K8/K$11*100 -> 15.59798 | L40: =L8/L$11*100 -> 16.636908 | M40: =M8/M$11*100 -> 17.832978 | ... P40: =P8/P$11*100 -> 16.758297 | R40: =AVERAGEIF(E40:Q40,"<>0") -> 15.958515
C41: Canada & Latin America (Other Americas) | F41: =F9/F$11*100 -> 0 | G41: =G9/G$11*100 -> 0 | H41: =H9/H$11*100 -> 6.0648895 | I41: =I9/I$11*100 -> 5.4756735 | J41: =J9/J$11*100 -> 5.5450814 | K41: =K9/K$11*100 -> 5.5606312 | L41: =L9/L$11*100 -> 5.5518143 | M41: =M9/M$11*100 -> 5.1592367 | ... P41: =P9/P$11*100 -> 5.959778 | R41: =AVERAGEIF(E41:Q41,"<>0") -> 5.6566646
C42: Hedging gains/(losses) | F42: =F10/F$11*100 -> -0.91320089 | G42: =G10/G$11*100 -> 0.26060211 | H42: =H10/H$11*100 -> -5.5874862 | I42: =I10/I$11*100 -> -0.81309819 | J42: =J10/J$11*100 -> -0.1524514 | K42: =K10/K$11*100 -> -0.10086318 | L42: =L10/L$11*100 -> 0.28111234 | M42: =M10/M$11*100 -> 0.096424091 | ... P42: =P10/P$11*100 -> 0.076774433 | R42: =AVERAGEIF(E42:Q42,"<>0") -> -0.55467022
F43: =SUM(F38:F42) -> 100 | G43: =SUM(G38:G42) -> 100 | H43: =SUM(H38:H42) -> 100 | I43: =SUM(I38:I42) -> 100 | J43: =SUM(J38:J42) -> 100 | K43: =SUM(K38:K42) -> 100 | L43: =SUM(L38:L42) -> 100 | M43: =SUM(M38:M42) -> 100 | ... P43: =SUM(P38:P42) -> 100
C45: Composition By Products / Services
C46: Search & Other | F46: =F15/F$24*100 -> 67.403952 | G46: =G15/G$24*100 -> 68.309571 | H46: =H15/H$24*100 -> 69.819574 | I46: =I15/I$24*100 -> 70.658676 | J46: =J15/J$24*100 -> 62.975058 | K46: =K15/K$24*100 -> 62.342219 | L46: =L15/L$24*100 -> 60.618324 | M46: =M15/M$24*100 -> 57.011839 | ... P46: =P15/P$24*100 -> 56.940929 | R46: =AVERAGEIF(E46:Q46,"<>0") -> 62.848231
C47: Youtube ads | F47: =F16/F$24*100 -> 24.586178 | G47: =G16/G$24*100 -> 22.028454 | H47: =H16/H$24*100 -> 20.04694 | I47: =I16/I$24*100 -> 17.27889 | J47: =J16/J$24*100 -> 7.3519462 | K47: =K16/K$24*100 -> 8.1531074 | L47: =L16/L$24*100 -> 9.3594963 | M47: =M16/M$24*100 -> 10.83237 | ... P47: =P16/P$24*100 -> 10.250688 | R47: =AVERAGEIF(E47:Q47,"<>0") -> 13.765751
...

Sheet Sharpe, Sortino
B3: GOOG Monthly Price Changes (5 years) | L3: United States 10-Year Bond Yield
B4: https://www.investing.com/equities/google-inc-c-historical-data | L4: https://www.investing.com/rates-bonds/u.s.-10-year-bond-yield-historical-data
B5: Jan'19 - Dec'23 | L5: Risk free rate average | O5: =[1]Sheet1!$E$6 -> 0.0246945 | S5: TEST (Manual calculation of Monthly Std Dev of Excess Returns - 5 Years)
F7: [1] | G7: [2] | H7: [1] - [2] | J7: [1] - [2] | S7: Sharpe | X7: Sortino
B8: Date | C8: Price | D8: Change % | F8: Change | G8: Monthly Risk free rate | H8: Monthly Excess returns | J8: Monthly Excess negative returns | S8: Average Monthly Excess Returns | U8: Difference Squared | V8: Monthly Std Dev of excess returns (σ) | X8: Average Monthly Excess Negative Returns | Y8: Difference Squared | Z8: Monthly Std Dev of excess returns (σ)
A9: 1 | B9: 45261 | C9: 140.93 | D9: 0.0523 | F9: =D9 -> 0.0523 | G9: =O$5/12 -> 0.002057875 | H9: =F9-G9 -> 0.050242125 | J9: =IF(H9<0,H9,"") | L9: Sharpe Ratio | O9: 1 Year | P9: 3 Years | Q9: 5 Years | S9: =AVERAGE(H9:H68) -> 0.017763792 | T9: 1 | U9: =(H9-S$9)^2 -> 0.0010548421 | V9: =(U70/T68)^(1/2) -> 0.077317381 | X9: =AVERAGE(J9:J68) -> -0.059362042 | Y9: =IF(J9="","",(J9-X$9)^2) | Z9: =(Y70/(COUNT(Y9:Y69)-1))^(1/2) -> 0.047827048
A10: 2 | B10: 45231 | C10: 133.92 | D10: 0.0688 | F10: =D10 -> 0.0688 | G10: =O$5/12 -> 0.002057875 | H10: =F10-G10 -> 0.066742125 | J10: =IF(H10<0,H10,"") | T10: 2 | U10: =(H10-S$9)^2 -> 0.0023988771 | Y10: =IF(J10="","",(J10-X$9)^2)
A11: 3 | B11: 45200 | C11: 125.3 | D11: -0.0497 | F11: =D11 -> -0.0497 | G11: =O$5/12 -> 0.002057875 | H11: =F11-G11 -> -0.051757875 | J11: =IF(H11<0,H11,"") -> -0.051757875 | L11: Monthly Std Dev of excess returns (σ) | O11: =STDEV.P(H9:H20) -> 0.076840081 | P11: =STDEV.P(H9:H44) -> 0.08181047 | Q11: =STDEV.P(H9:H68) -> 0.077317381 | T11: 3 | U11: =(H11-S$9)^2 -> 0.0048332621 | Y11: =IF(J11="","",(J11-X$9)^2) -> 5.7823351e-05
A12: 4 | B12: 45170 | C12: 131.85 | D12: -0.04 | F12: =D12 -> -0.04 | G12: =O$5/12 -> 0.002057875 | H12: =F12-G12 -> -0.042057875 | J12: =IF(H12<0,H12,"") -> -0.042057875 | L12: Monthly Portfolio return (Rp) | O12: =(1+O19)^(1/12)-1 -> 0.029115297 | P12: =(1+P19)^(1/12)-1 -> 0.011981205 | Q12: =(1+Q19)^(1/12)-1 -> 0.015555261 | T12: 4 | U12: =(H12-S$9)^2 -> 0.0035786318 | Y12: =IF(J12="","",(J12-X$9)^2) -> 0.00029943418
A13: 5 | B13: 45139 | C13: 137.35 | D13: 0.0319 | F13: =D13 -> 0.0319 | G13: =O$5/12 -> 0.002057875 | H13: =F13-G13 -> 0.029842125 | J13: =IF(H13<0,H13,"") | L13: Monthly Risk-free return - US 10Yr Yield (Rf) | O13: =O20/12 -> 0.002057875 | P13: =P20/12 -> 0.002057875 | Q13: =Q20/12 -> 0.002057875 | T13: 5 | U13: =(H13-S$9)^2 -> 0.00014588614 | Y13: =IF(J13="","",(J13-X$9)^2)
A14: 6 | B14: 45108 | C14: 133.11 | D14: 0.1004 | F14: =D14 -> 0.1004 | G14: =O$5/12 -> 0.002057875 | H14: =F14-G14 -> 0.098342125 | J14: =IF(H14<0,H14,"") | L14: Excess return (Rp - Rf) | O14: =O12-O13 -> 0.027057422 | P14: =P12-P13 -> 0.0099233302 | Q14: =Q12-Q13 -> 0.013497386 | T14: 6 | U14: =(H14-S$9)^2 -> 0.0064928678 | Y14: =IF(J14="","",(J14-X$9)^2)
A15: 7 | B15: 45078 | C15: 120.97 | D15: -0.0195 | F15: =D15 -> -0.0195 | G15: =O$5/12 -> 0.002057875 | H15: =F15-G15 -> -0.021557875 | J15: =IF(H15<0,H15,"") -> -0.021557875 | T15: 7 | U15: =(H15-S$9)^2 -> 0.0015461935 | Y15: =IF(J15="","",(J15-X$9)^2) -> 0.001429155
A16: 8 | B16: 45047 | C16: 123.37 | D16: 0.14 | F16: =D16 -> 0.14 | G16: =O$5/12 -> 0.002057875 | H16: =F16-G16 -> 0.13794212 | J16: =IF(H16<0,H16,"") | L16: Monthly Sharpe Ratio ( [Rp - Rf] / σ ) | O16: =O14/O11 -> 0.35212641 | P16: =P14/P11 -> 0.12129658 | Q16: =Q14/Q11 -> 0.17457117 | T16: 8 | U16: =(H16-S$9)^2 -> 0.014442832 | Y16: =IF(J16="","",(J16-X$9)^2)
A17: 9 | B17: 45017 | C17: 108.22 | D17: 0.0406 | F17: =D17 -> 0.0406 | G17: =O$5/12 -> 0.002057875 | H17: =F17-G17 -> 0.038542125 | J17: =IF(H17<0,H17,"") | T17: 9 | U17: =(H17-S$9)^2 -> 0.00043173914 | Y17: =IF(J17="","",(J17-X$9)^2)
A18: 10 | B18: 44986 | C18: 104 | D18: 0.1517 | F18: =D18 -> 0.1517 | G18: =O$5/12 -> 0.002057875 | H18: =F18-G18 -> 0.14964212 | J18: =IF(H18<0,H18,"") | L18: Annualized Std Dev of excess returns (σ) | O18: =O11*12^(1/2) -> 0.26618185 | P18: =P11*12^(1/2) -> 0.28339978 | Q18: =Q11*12^(1/2) -> 0.26783526 | T18: 10 | U18: =(H18-S$9)^2 -> 0.017391895 | Y18: =IF(J18="","",(J18-X$9)^2)
A19: 11 | B19: 44958 | C19: 90.3 | D19: -0.0958 | F19: =D19 -> -0.0958 | G19: =O$5/12 -> 0.002057875 | H19: =F19-G19 -> -0.097857875 | J19: =IF(H19<0,H19,"") -> -0.097857875 | L19: Annualized Portfolio return (Rp) | O19: =($C$9/$C$20)^(1/($A$20/12))-1 -> 0.41113447 | P19: =($C$9/$C$44)^(1/($A$44/12))-1 -> 0.15363749 | Q19: =($C$9/$C$68)^(1/($A$68/12))-1 -> 0.20349066 | T19: 11 | U19: =(H19-S$9)^2 -> 0.01336837 | Y19: =IF(J19="","",(J19-X$9)^2) -> 0.0014819292
A20: 12 | B20: 44927 | C20: 99.87 | D20: 0.1255 | F20: =D20 -> 0.1255 | G20: =O$5/12 -> 0.002057875 | H20: =F20-G20 -> 0.12344212 | J20: =IF(H20<0,H20,"") | L20: Annualized Risk-free return - US 10Yr Yield (Rf) | O20: =$O$5 -> 0.0246945 | P20: =$O$5 -> 0.0246945 | Q20: =$O$5 -> 0.0246945 | T20: 12 | U20: =(H20-S$9)^2 -> 0.01116791 | Y20: =IF(J20="","",(J20-X$9)^2)
A21: 13 | B21: 44896 | C21: 88.73 | D21: -0.1254 | F21: =D21 -> -0.1254 | G21: =O$5/12 -> 0.002057875 | H21: =F21-G21 -> -0.12745787 | J21: =IF(H21<0,H21,"") -> -0.12745787 | L21: Excess return (Rp - Rf) | O21: =O19-O20 -> 0.38643997 | P21: =P19-P20 -> 0.12894299 | Q21: =Q19-Q20 -> 0.17879616 | T21: 13 | U21: =(H21-S$9)^2 -> 0.021089332 | Y21: =IF(J21="","",(J21-X$9)^2) -> 0.0046370425
A22: 14 | B22: 44866 | C22: 101.45 | D22: 0.0717 | F22: =D22 -> 0.0717 | G22: =O$5/12 -> 0.002057875 | H22: =F22-G22 -> 0.069642125 | J22: =IF(H22<0,H22,"") | T22: 14 | U22: =(H22-S$9)^2 -> 0.0026913615 | Y22: =IF(J22="","",(J22-X$9)^2)
A23: 15 | B23: 44835 | C23: 94.66 | D23: -0.0155 | F23: =D23 -> -0.0155 | G23: =O$5/12 -> 0.002057875 | H23: =F23-G23 -> -0.017557875 | J23: =IF(H23<0,H23,"") -> -0.017557875 | L23: Annualized Sharpe Ratio ( [Rp - Rf] / σ ) | O23: =O21/O18 -> 1.4517894 | P23: =P21/P18 -> 0.4549862 | Q23: =Q21/Q18 -> 0.66756019 | T23: 15 | U23: =(H23-S$9)^2 -> 0.0012476201 | Y23: =IF(J23="","",(J23-X$9)^2) -> 0.0017475884
A24: 16 | B24: 44805 | C24: 96.15 | D24: -0.1191 | F24: =D24 -> -0.1191 | G24: =O$5/12 -> 0.002057875 | H24: =F24-G24 -> -0.12115787 | J24: =IF(H24<0,H24,"") -> -0.12115787 | T24: 16 | U24: =(H24-S$9)^2 -> 0.019299229 | Y24: =IF(J24="","",(J24-X$9)^2) -> 0.003818725
A25: 17 | B25: 44774 | C25: 109.15 | D25: -0.0642 | F25: =D25 -> -0.0642 | G25: =O$5/12 -> 0.002057875 | H25: =F25-G25 -> -0.066257875 | J25: =IF(H25<0,H25,"") -> -0.066257875 | T25: 17 | U25: =(H25-S$9)^2 -> 0.0070596405 | Y25: =IF(J25="","",(J25-X$9)^2) -> 4.7552517e-05
A26: 18 | B26: 44743 | C26: 116.64 | D26: 0.0664 | F26: =D26 -> 0.0664 | G26: =O$5/12 -> 0.002057875 | H26: =F26-G26 -> 0.064342125 | J26: =IF(H26<0,H26,"") | L26: Sortino Ratio | O26: 1 Year | P26: 3 Years | Q26: 5 Years | T26: 18 | U26: =(H26-S$9)^2 -> 0.0021695411 | Y26: =IF(J26="","",(J26-X$9)^2)
A27: 19 | B27: 44713 | C27: 109.37 | D27: -0.0409 | F27: =D27 -> -0.0409 | G27: =O$5/12 -> 0.002057875 | H27: =F27-G27 -> -0.042957875 | J27: =IF(H27<0,H27,"") -> -0.042957875 | T27: 19 | U27: =(H27-S$9)^2 -> 0.0036871208 | Y27: =IF(J27="","",(J27-X$9)^2) -> 0.00026909668
A28: 20 | B28: 44682 | C28: 114.04 | D28: -0.0081 | F28: =D28 -> -0.0081 | G28: =O$5/12 -> 0.002057875 | H28: =F28-G28 -> -0.010157875 | J28: =IF(H28<0,H28,"") -> -0.010157875 | L28: Monthly Std Dev of excess negative returns (σd) | O28: =_xlfn.STDEV.S(J9:J20) -> 0.032257971 | P28: =_xlfn.STDEV.S(J9:J44) -> 0.049967775 | Q28: =_xlfn.STDEV.S(J9:J68) -> 0.047827048 | T28: 20 | U28: =(H28-S$9)^2 -> 0.00077961947 | Y28: =IF(J28="","",(J28-X$9)^2) -> 0.00242105
A29: 21 | B29: 44652 | C29: 114.97 | D29: -0.1767 | F29: =D29 -> -0.1767 | G29: =O$5/12 -> 0.002057875 | H29: =F29-G29 -> -0.17875788 | J29: =IF(H29<0,H29,"") -> -0.17875788 | L29: Monthly Portfolio return (Rp) | O29: =(1+O36)^(1/12)-1 -> 0.029115297 | P29: =(1+P36)^(1/12)-1 -> 0.011981205 | Q29: =(1+Q36)^(1/12)-1 -> 0.015555261 | T29: 21 | U29: =(H29-S$9)^2 -> 0.038620765 | Y29: =IF(J29="","",(J29-X$9)^2) -> 0.014255365
A30: 22 | B30: 44621 | C30: 139.65 | D30: 0.0353 | F30: =D30 -> 0.0353 | G30: =O$5/12 -> 0.002057875 | H30: =F30-G30 -> 0.033242125 | J30: =IF(H30<0,H30,"") | L30: Monthly Risk-free return - US 10Yr Yield (Rf) | O30: =O37/12 -> 0.002057875 | P30: =P37/12 -> 0.002057875 | Q30: =Q37/12 -> 0.002057875 | T30: 22 | U30: =(H30-S$9)^2 -> 0.0002395788 | Y30: =IF(J30="","",(J30-X$9)^2)
A31: 23 | B31: 44593 | C31: 134.89 | D31: -0.006 | F31: =D31 -> -0.006 | G31: =O$5/12 -> 0.002057875 | H31: =F31-G31 -> -0.008057875 | J31: =IF(H31<0,H31,"") -> -0.008057875 | L31: Excess return (Rp - Rf) | O31: =O29-O30 -> 0.027057422 | P31: =P29-P30 -> 0.0099233302 | Q31: =Q29-Q30 -> 0.013497386 | T31: 23 | U31: =(H31-S$9)^2 -> 0.00066675847 | Y31: =IF(J31="","",(J31-X$9)^2) -> 0.0026321175
A32: 24 | B32: 44562 | C32: 135.7 | D32: -0.0621 | F32: =D32 -> -0.0621 | G32: =O$5/12 -> 0.002057875 | H32: =F32-G32 -> -0.064157875 | J32: =IF(H32<0,H32,"") -> -0.064157875 | T32: 24 | U32: =(H32-S$9)^2 -> 0.0067111595 | Y32: =IF(J32="","",(J32-X$9)^2) -> 2.3000017e-05
A33: 25 | B33: 44531 | C33: 144.68 | D33: 0.0156 | F33: =D33 -> 0.0156 | G33: =O$5/12 -> 0.002057875 | H33: =F33-G33 -> 0.013542125 | J33: =IF(H33<0,H33,"") | L33: Monthly Sortino Ratio ( [Rp - Rf] / σ ) | O33: =O31/O28 -> 0.83878251 | P33: =P31/P28 -> 0.1985946 | Q33: =Q31/Q28 -> 0.2822124 | T33: 25 | U33: =(H33-S$9)^2 -> 1.7822469e-05 | Y33: =IF(J33="","",(J33-X$9)^2)
A34: 26 | B34: 44501 | C34: 142.45 | D34: -0.0392 | F34: =D34 -> -0.0392 | G34: =O$5/12 -> 0.002057875 | H34: =F34-G34 -> -0.041257875 | J34: =IF(H34<0,H34,"") -> -0.041257875 | T34: 26 | U34: =(H34-S$9)^2 -> 0.0034835571 | Y34: =IF(J34="","",(J34-X$9)^2) -> 0.00032776085
A35: 27 | B35: 44470 | C35: 148.27 | D35: 0.1126 | F35: =D35 -> 0.1126 | G35: =O$5/12 -> 0.002057875 | H35: =F35-G35 -> 0.11054213 | J35: =IF(H35<0,H35,"") | L35: Annualized Std Dev of excess negative returns (σ) | O35: =O28*12^(1/2) -> 0.11174489 | P35: =P28*12^(1/2) -> 0.17309345 | Q35: =Q28*12^(1/2) -> 0.16567775 | T35: 27 | U35: =(H35-S$9)^2 -> 0.0086078191 | Y35: =IF(J35="","",(J35-X$9)^2)
A36: 28 | B36: 44440 | C36: 133.27 | D36: -0.0838 | F36: =D36 -> -0.0838 | G36: =O$5/12 -> 0.002057875 | H36: =F36-G36 -> -0.085857875 | J36: =IF(H36<0,H36,"") -> -0.085857875 | L36: Annualized Portfolio return (Rp) | O36: =($C$9/$C$20)^(1/($A$20/12))-1 -> 0.41113447 | P36: =($C$9/$C$44)^(1/($A$44/12))-1 -> 0.15363749 | Q36: =($C$9/$C$68)^(1/($A$68/12))-1 -> 0.20349066 | T36: 28 | U36: =(H36-S$9)^2 -> 0.01073745 | Y36: =IF(J36="","",(J36-X$9)^2) -> 0.00070202918
A37: 29 | B37: 44409 | C37: 145.46 | D37: 0.0757 | F37: =D37 -> 0.0757 | G37: =O$5/12 -> 0.002057875 | H37: =F37-G37 -> 0.073642125 | J37: =IF(H37<0,H37,"") | L37: Annualized Risk-free return - US 10Yr Yield (Rf) | O37: =$O$5 -> 0.0246945 | P37: =$O$5 -> 0.0246945 | Q37: =$O$5 -> 0.0246945 | T37: 29 | U37: =(H37-S$9)^2 -> 0.0031223881 | Y37: =IF(J37="","",(J37-X$9)^2)
A38: 30 | B38: 44378 | C38: 135.22 | D38: 0.079 | F38: =D38 -> 0.079 | G38: =O$5/12 -> 0.002057875 | H38: =F38-G38 -> 0.076942125 | J38: =IF(H38<0,H38,"") | L38: Excess return (Rp - Rf) | O38: =O36-O37 -> 0.38643997 | P38: =P36-P37 -> 0.12894299 | Q38: =Q36-Q37 -> 0.17879616 | T38: 30 | U38: =(H38-S$9)^2 -> 0.0035020751 | Y38: =IF(J38="","",(J38-X$9)^2)
A39: 31 | B39: 44348 | C39: 125.32 | D39: 0.0393 | F39: =D39 -> 0.0393 | G39: =O$5/12 -> 0.002057875 | H39: =F39-G39 -> 0.037242125 | J39: =IF(H39<0,H39,"") | T39: 31 | U39: =(H39-S$9)^2 -> 0.00037940547 | Y39: =IF(J39="","",(J39-X$9)^2)
A40: 32 | B40: 44317 | C40: 120.58 | D40: 0.0006 | F40: =D40 -> 0.0006 | G40: =O$5/12 -> 0.002057875 | H40: =F40-G40 -> -0.001457875 | J40: =IF(H40<0,H40,"") -> -0.001457875 | L40: Annualized Sortino Ratio ( [Rp - Rf] / σd ) | O40: =O38/O35 -> 3.458234 | P40: =P38/P35 -> 0.74493281 | Q40: =Q38/Q35 -> 1.0791802 | T40: 32 | U40: =(H40-S$9)^2 -> 0.00036947247 | Y40: =IF(J40="","",(J40-X$9)^2) -> 0.0033528925
A41: 33 | B41: 44287 | C41: 120.51 | D41: 0.1651 | F41: =D41 -> 0.1651 | G41: =O$5/12 -> 0.002057875 | H41: =F41-G41 -> 0.16304213 | J41: =IF(H41<0,H41,"") | T41: 33 | U41: =(H41-S$9)^2 -> 0.021105794 | Y41: =IF(J41="","",(J41-X$9)^2)
A42: 34 | B42: 44256 | C42: 103.43 | D42: 0.0156 | F42: =D42 -> 0.0156 | G42: =O$5/12 -> 0.002057875 | H42: =F42-G42 -> 0.013542125 | J42: =IF(H42<0,H42,"") | T42: 34 | U42: =(H42-S$9)^2 -> 1.7822469e-05 | Y42: =IF(J42="","",(J42-X$9)^2)
A43: 35 | B43: 44228 | C43: 101.84 | D43: 0.1096 | F43: =D43 -> 0.1096 | G43: =O$5/12 -> 0.002057875 | H43: =F43-G43 -> 0.10754213 | J43: =IF(H43<0,H43,"") | T43: 35 | U43: =(H43-S$9)^2 -> 0.0080601491 | Y43: =IF(J43="","",(J43-X$9)^2)
...

Sheet Projections
F1: < Figures are in millions >
F2: Y/E 31/12
F3: 2013 | G3: 2014 | H3: 2015 | I3: 2016 | J3: 2017 | K3: 2018 | L3: 2019 | M3: 2020 | N3: 2021 | O3: 2022 | P3: 2023 | Q3: 2024 | R3: 2025 | S3: 2026 | T3: 2027 | U3: 2028 | V3: 2029 | W3: 2030 | X3: 2031 | Y3: 2032 | Z3: 2033 | AA3: 2034 | AC3: CAGR
T6: Average Growth Rate = | U6: =FS!R66 -> 18.978528 | V6: %
B7: P&L
B8: Revenue | F8: 55519 | G8: 66001 | H8: 74989 | I8: 90272 | J8: 110855 | K8: 136819 | L8: 161857 | M8: 182527 | N8: 257637 | O8: 282836 | P8: 307394 | Q8: =P8*(1+$U6/100) -> 365732.86 | R8: =Q8*(1+$U6/100) -> 435143.57 | S8: =R8*(1+$U6/100) -> 517727.42 | T8: =S8*(1+$U6/100) -> 615984.46 | U8: =T8*(1+$U6/100) -> 732889.24 | V8: =U8*(1+$U6/100) -> 871980.84 | W8: =V8*(1+$U6/100) -> 1037470 | X8: =W8*(1+$U6/100) -> 1234366.5 | ... AA8: =Z8*(1+$U6/100) -> 2078978
B9: Cost of Revenue | F9: 21993 | G9: 25691 | H9: 28164 | I9: 35138 | J9: 45583 | K9: 59549 | L9: 71896 | M9: 84732 | N9: 110939 | O9: 126203 | P9: 133332 | Q9: =Q8-Q10 -> 212271.04 | R9: =R8-R10 -> 252556.96 | S9: =S8-S10 -> 300488.56 | T9: =T8-T10 -> 357516.86 | U9: =U8-U10 -> 425368.3 | V9: =V8-V10 -> 506096.95 | W9: =W8-W10 -> 602146.7 | X9: =X8-X10 -> 716425.28 | ... AA9: =AA8-AA10 -> 1206637.1
B10: Gross Profit | F10: =F8-F9 -> 33526 | G10: =G8-G9 -> 40310 | H10: =H8-H9 -> 46825 | I10: =I8-I9 -> 55134 | J10: =J8-J9 -> 65272 | K10: =K8-K9 -> 77270 | L10: =L8-L9 -> 89961 | M10: =M8-M9 -> 97795 | ... P10: =P8-P9 -> 174062 | Q10: =Q8*($Q11/100) -> 153461.81 | R10: =R8*($Q11/100) -> 182586.61 | S10: =S8*($Q11/100) -> 217238.86 | T10: =T8*($Q11/100) -> 258467.59 | U10: =U8*($Q11/100) -> 307520.94 | V10: =V8*($Q11/100) -> 365883.89 | W10: =W8*($Q11/100) -> 435323.26 | X10: =X8*($Q11/100) -> 517941.21 | ... AA10: =AA8*($Q11/100) -> 872340.92
C11: GP margin (%) | F11: =IFERROR(F9/F8*100,0) -> 39.613466 | G11: =IFERROR(G9/G8*100,0) -> 38.925168 | H11: =IFERROR(H9/H8*100,0) -> 37.557508 | I11: =IFERROR(I9/I8*100,0) -> 38.924583 | J11: =IFERROR(J9/J8*100,0) -> 41.11948 | K11: =IFERROR(K9/K8*100,0) -> 43.523926 | L11: =IFERROR(L9/L8*100,0) -> 44.419457 | M11: =IFERROR(M9/M8*100,0) -> 46.421625 | ... P11: =IFERROR(P9/P8*100,0) -> 43.374952 | Q11: =AVERAGE(E11:P11) -> 41.960084
B13: Research & Development | F13: 7137 | G13: 9832 | H13: 12282 | I13: 13948 | J13: 16625 | K13: 21419 | L13: 26018 | M13: 27573 | N13: 31562 | O13: 39500 | P13: 45427
B14: Sales & Marketing | F14: 6554 | G14: 8131 | H14: 9047 | I14: 10485 | J14: 12893 | K14: 16333 | L14: 18464 | M14: 17946 | N14: 22912 | O14: 26567 | P14: 27917
B15: General & Admin | F15: 4432 | G15: 5851 | H15: 6136 | I15: 6985 | J15: 6840 | K15: 6923 | L15: 9551 | M15: 11052 | N15: 13510 | O15: 15724 | P15: 16425
B16: European Commission fines | F16: 0 | G16: 0 | H16: 0 | I16: 0 | J16: 2736 | K16: 5071 | L16: 1697 | M16: 0 | N16: 0 | O16: 0 | P16: 0
B17: Total Cost & Expenses | F17: =SUM(F13:F16) -> 18123 | G17: =SUM(G13:G16) -> 23814 | H17: =SUM(H13:H16) -> 27465 | I17: =SUM(I13:I16) -> 31418 | J17: =SUM(J13:J16) -> 39094 | K17: =SUM(K13:K16) -> 49746 | L17: =SUM(L13:L16) -> 55730 | M17: =SUM(M13:M16) -> 56571 | ... P17: =SUM(P13:P16) -> 89769 | Q17: =Q10-Q19 -> 61454.329 | R17: =R10-R19 -> 73117.457 | S17: =S10-S19 -> 86994.074 | T17: =T10-T19 -> 103504.27 | U17: =U10-U19 -> 123147.86 | V17: =V10-V19 -> 146519.51 | W17: =W10-W19 -> 174326.75 | X17: =X10-X19 -> 207411.4 | ... AA17: =AA10-AA19 -> 349332.03
B19: Operating Income | F19: =F10-F17 -> 15403 | G19: =G10-G17 -> 16496 | H19: =H10-H17 -> 19360 | I19: =I10-I17 -> 23716 | J19: =J10-J17 -> 26178 | K19: =K10-K17 -> 27524 | L19: =L10-L17 -> 34231 | M19: =M10-M17 -> 41224 | ... P19: =P10-P17 -> 84293 | Q19: =Q8*($Q20/100) -> 92007.483 | R19: =R8*($Q20/100) -> 109469.15 | S19: =S8*($Q20/100) -> 130244.78 | T19: =T8*($Q20/100) -> 154963.33 | U19: =U8*($Q20/100) -> 184373.08 | V19: =V8*($Q20/100) -> 219364.38 | W19: =W8*($Q20/100) -> 260996.51 | X19: =X8*($Q20/100) -> 310529.81 | ... AA19: =AA8*($Q20/100) -> 523008.89
C20: Operating margin (%) | F20: =IFERROR(F19/F8*100,0) -> 27.743655 | G20: =IFERROR(G19/G8*100,0) -> 24.993561 | H20: =IFERROR(H19/H8*100,0) -> 25.81712 | I20: =IFERROR(I19/I8*100,0) -> 26.271712 | J20: =IFERROR(J19/J8*100,0) -> 23.614632 | K20: =IFERROR(K19/K8*100,0) -> 20.117089 | L20: =IFERROR(L19/L8*100,0) -> 21.148915 | M20: =IFERROR(M19/M8*100,0) -> 22.585152 | ... P20: =IFERROR(P19/P8*100,0) -> 27.42181 | Q20: =AVERAGE(E20:P20) -> 25.157019
B22: Other Income / (expense), Net | F22: =496-427 -> 69 | G22: =763+516 -> 1279 | H22: 291 | I22: 434 | J22: 1015 | K22: 7389 | L22: 5394 | M22: 6858 | N22: 12020 | O22: -3514 | P22: 1424 | Q22: =Q8*(FS!$R$93/100) -> 6917.4888 | R22: =R8*(FS!$R$93/100) -> 8230.3263 | S22: =S8*(FS!$R$93/100) -> 9792.3211 | T22: =T8*(FS!$R$93/100) -> 11650.76 | U22: =U8*(FS!$R$93/100) -> 13861.902 | V22: =V8*(FS!$R$93/100) -> 16492.687 | W22: =W8*(FS!$R$93/100) -> 19622.757 | X22: =X8*(FS!$R$93/100) -> 23346.867 | ... AA22: =AA8*(FS!$R$93/100) -> 39321.89
B24: Income before taxation | F24: =F19+F22 -> 15472 | G24: =G19+G22 -> 17775 | H24: =H19+H22 -> 19651 | I24: =I19+I22 -> 24150 | J24: =J19+J22 -> 27193 | K24: =K19+K22 -> 34913 | L24: =L19+L22 -> 39625 | M24: =M19+M22 -> 48082 | ... AA24: =AA19+AA22 -> 562330.78
B26: Provision for income taxes | F26: 2739 | G26: 3639 | H26: 3303 | I26: 4672 | J26: 14531 | K26: 4177 | L26: 5282 | M26: 7813 | N26: 14701 | O26: 11356 | P26: 11922 | Q26: =Q24-Q28 -> 19255.415 | R26: =R24*(FS!$R$97/100) -> 20863.487 | S26: =S24*(FS!$R$97/100) -> 24823.07 | T26: =T24*(FS!$R$97/100) -> 29534.123 | U26: =U24*(FS!$R$97/100) -> 35139.265 | V26: =V24*(FS!$R$97/100) -> 41808.18 | W26: =W24*(FS!$R$97/100) -> 49742.757 | X26: =X24*(FS!$R$97/100) -> 59183.2 | Y26: =Y24*(FS!$R$97/100) -> 70415.301 | ... AA26: =AA24*(FS!$R$97/100) -> 99679.126
B28: Net Income | F28: =F24-F26 -> 12733 | G28: =G24-G26 -> 14136 | H28: =H24-H26 -> 16348 | I28: =I24-I26 -> 19478 | J28: =J24-J26 -> 12662 | K28: =K24-K26 -> 30736 | L28: =L24-L26 -> 34343 | M28: =M24-M26 -> 40269 | ... P28: =P24-P26 -> 73795 | Q28: =Q8*($Q29/100) -> 79669.557 | R28: =R8*($Q29/100) -> 94789.667 | S28: =S8*($Q29/100) -> 112779.35 | T28: =T8*($Q29/100) -> 134183.21 | U28: =U8*($Q29/100) -> 159649.21 | V28: =V8*($Q29/100) -> 189948.28 | W28: =W8*($Q29/100) -> 225997.67 | X28: =X8*($Q29/100) -> 268888.7 | ... AA28: =AA8*($Q29/100) -> 452874.98
C29: Net income margin (%) | F29: =IFERROR(F28/F8*100,0) -> 22.934491 | G29: =IFERROR(G28/G8*100,0) -> 21.417857 | H29: =IFERROR(H28/H8*100,0) -> 21.800531 | I29: =IFERROR(I28/I8*100,0) -> 21.577012 | J29: =IFERROR(J28/J8*100,0) -> 11.422128 | K29: =IFERROR(K28/K8*100,0) -> 22.464716 | L29: =IFERROR(L28/L8*100,0) -> 21.218112 | M29: =IFERROR(M28/M8*100,0) -> 22.061942 | ... P29: =IFERROR(P28/P8*100,0) -> 24.006649 | Q29: =AVERAGE(E29:P29) -> 21.783538
C33: Valuation Multiples / Shareholder ratios
C34: No. of Shares | F34: 671.664 | G34: 680.172 | H34: 687.348 | I34: 691.293 | J34: 694.783 | K34: 695.556 | L34: 688.335 | M34: 675.222 | N34: =6006+909+6438 -> 13353 | O34: =5994+887+6182 -> 13063 | P34: =5922+877+5831 -> 12630 | Q34: 12630 | R34: 12630 | S34: 12630 | T34: 12630 | U34: 12630 | V34: 12630 | W34: 12630 | X34: 12630 | Y34: 12630 | Z34: 12630 | AA34: 12631
C35: Share Price | F35: 27.91 | G35: 26.25 | H35: 37.94 | I35: 38.59 | J35: 52.32 | K35: 51.78 | L35: 66.851 | M35: 87.594 | N35: 146 | O35: 88.73 | P35: 140.93 | Q35: =Q36*$Q37 -> 183.57059 | R35: =R36*$Q37 -> 218.40959 | S35: =S36*$Q37 -> 259.86052 | T35: =T36*$Q37 -> 309.17822 | U35: =U36*$Q37 -> 367.8557 | V35: =V36*$Q37 -> 437.66929 | W35: =W36*$Q37 -> 520.73248 | X35: =X36*$Q37 -> 619.55984 | ... AA35: =AA36*$Q37 -> 1043.4092 | AC35: =((AA35/P35)^(1/($AA$3-$P$3))-1)*100 -> 19.96126
C36: EPS | F36: =IFERROR(F28/(F34*20),0) -> 0.94786977 | G36: =IFERROR(G28/(G34*20),0) -> 1.0391489 | H36: =IFERROR(H28/(H34*20),0) -> 1.1892084 | I36: =IFERROR(I28/(I34*20),0) -> 1.4088093 | J36: =IFERROR(J28/(J34*20),0) -> 0.91121976 | K36: =IFERROR(K28/(K34*20),0) -> 2.2094555 | L36: =IFERROR(L28/(L34*20),0) -> 2.4946429 | M36: =IFERROR(M28/(M34*20),0) -> 2.9819082 | N36: =IFERROR(N28/N34,0) -> 5.6940762 | O36: =IFERROR(O28/O34,0) -> 4.5909822 | P36: =IFERROR(P28/P34,0) -> 5.8428345 | Q36: =IFERROR(Q28/Q34,0) -> 6.3079618 | R36: =IFERROR(R28/R34,0) -> 7.5051201 | S36: =IFERROR(S28/S34,0) -> 8.9294814 | T36: =IFERROR(T28/T34,0) -> 10.624166 | U36: =IFERROR(U28/U34,0) -> 12.640476 | ... AA36: =IFERROR(AA28/AA34,0) -> 35.854246
C37: P/E | F37: =F35/F36 -> 29.444973 | G37: =G35/G36 -> 25.261057 | H37: =H35/H36 -> 31.903576 | I37: =I35/I36 -> 27.391926 | J37: =J35/J36 -> 57.417543 | K37: =K35/K36 -> 23.435639 | L37: =L35/L36 -> 26.797824 | M37: =M35/M36 -> 29.37515 | ... P37: =P35/P36 -> 24.120142 | Q37: =AVERAGE(E37:P37) -> 29.101412

Sheet SWOT
O2: Notes
B3: Strengths
C4: Google Services
D5: Advertising (Search, Youtube, Admob+Adsense+Admanager) | O5: 80% of total revenue
D6: Subscription, platform & devices (youtube premium, google play, pixel devices) | O6: 11% of total revenue
C8: Google Cloud | O8: 8% of total reveue
B12: Weaknesses
B20: Opportunities
C21: Other Bets | O21: < 1% of total revenue
C23: AI LLMs
D24: Deep Learning Architectures --> Transformer (neural network architecture) | O24: - Introduced in 2017
O25: - Led to Bidirectional Encoder Representations from Tranformers (BERT) in 2019
D27: Bidirectional Encoder Representations from Tranformers (BERT) | O27: - Helps search understand the intent of user search queries better
C29: Google Cloud | O29: - Average annual growth rate : 39.06%
C31: Google DeepMind | O31: - Google DeepMind is an Alphabet subsidiary focusing on artificial intelligence, machine learning, and neuroscience research
O32: - Google DeepMind Technologies Limited is a British-American artificial intelligence research laboratory which serves as a subsidiary of Google
O33: - Number of employees: c. 2,600 (2024)
C35: Vertex AI | O35: - Vertex AI platform is employed by data scientists and machine learning engineers who are looking to automate or streamline their machine learning projects.
O36: - Much of the automation happens through Vertex AI Pipelines, which orchestrate your ML lifecycle or workflow in a serverless fashion
O37: - Vertex AI Studio is a Google Cloud console tool for rapidly prototyping and testing generative AI models
C39: Duet AI | O39: - Duet AI is a productivity tool that provides assistance to developers, operators, and data scientists while they use Google Cloud products.
O40: - Duet AI is GCP native code assistance tool for building, running and operating code
B47: Threats
