Workbook

Sheet Overall
B2: SUMMARY
H3: Share price | K3: Profit Margins | T3: Valuations Multiples | AC3: Solvency | AL3: Efficiency | AU3: Risk
H4: CAGR | K4: GPM | N4: OM | Q4: NPM | T4: PE | W4: EPS | Z4: Dividend Yield | AC4: Debt Ratio | AF4: Debt - Equity | AI4: Debt - Revenue | AL4: IT | AO4: RT | AR4: PT | AU4: Sharpe Ratio | AX4: Sortino Ratio
B5: Base year | D5: Y/E | E5: Updated As At | F5: MC | G5: Share price at Y/E | H5: Current | I5: 3 years | J5: 5 years | K5: Current | L5: 3 years | M5: 5 years | N5: Current | O5: 3 years | P5: 5 years | Q5: Current | R5: 3 years | S5: 5 years | T5: Current | U5: 3 years | V5: 5 years | W5: Current | X5: 3 years | Y5: 5 years | Z5: Current | AA5: 3 years | AB5: 5 years | AC5: Current | AD5: 3 years | AE5: 5 years | AF5: Current | AG5: 3 years | AH5: 5 years | AI5: Current | AJ5: 3 years | AK5: 5 years | AL5: Current | AM5: 3 years | AN5: 5 years | AO5: Current | AP5: 3 years | AQ5: 5 years | AR5: Current | AS5: 3 years | AT5: 5 years | AU5: Current | AV5: 3 years | AW5: 5 years | AX5: Current | AY5: 3 years | AZ5: 5 years
B6: 2024 | D6: 31/01 | E6: 2024 | F6: =OFFSET(FS!P111,0,E$6-B$6) -> 1516099.2 | G6: =OFFSET(FS!P105,0,E$6-B$6) -> 61.53 | H6: =((OFFSET(FS!P105,0,E$6-B$6)/OFFSET(FS!P105,0,-1+E$6-B$6))^(1/1)-1)*100 -> 214.89253 | I6: =((OFFSET(FS!P105,0,E$6-B$6)/OFFSET(FS!P105,0,-2+E$6-B$6))^(1/3)-1)*100 -> 35.945878 | J6: =((OFFSET(FS!P105,0,E$6-B$6)/OFFSET(FS!P105,0,-4+E$6-B$6))^(1/5)-1)*100 -> 59.771711 | K6: =OFFSET(FS!P80,0,0+E$6-B$6) -> 72.717573 | L6: =AVERAGE(OFFSET(FS!P80,0,-2+E$6-B$6):OFFSET(FS!P80,0,E$6-B$6)) -> 64.8585 | M6: =AVERAGE(OFFSET(FS!P80,0,-4+E$6-B$6):OFFSET(FS!P80,0,E$6-B$6)) -> 63.781941 | N6: =OFFSET(FS!P89,0,0+E$6-B$6) -> 54.121664 | O6: =AVERAGE(OFFSET(FS!P89,0,-2+E$6-B$6):OFFSET(FS!P89,0,E$6-B$6)) -> 35.696303 | P6: =AVERAGE(OFFSET(FS!P89,0,-4+E$6-B$6):OFFSET(FS!P89,0,E$6-B$6)) -> 32.066873 | Q6: =OFFSET(FS!P98,0,0+E$6-B$6) -> 48.849348 | R6: =AVERAGE(OFFSET(FS!P98,0,-2+E$6-B$6):OFFSET(FS!P98,0,E$6-B$6)) -> 33.758883 | S6: =AVERAGE(OFFSET(FS!P98,0,-4+E$6-B$6):OFFSET(FS!P98,0,E$6-B$6)) -> 30.572949 | T6: =OFFSET(FS!P107,0,0+E$6-B$6) -> 50.944194 | U6: =AVERAGE(OFFSET(FS!P107,0,-2+E$6-B$6):OFFSET(FS!P107,0,E$6-B$6)) -> 74.730658 | V6: =AVERAGE(OFFSET(FS!P107,0,-4+E$6-B$6):OFFSET(FS!P107,0,E$6-B$6)) -> 70.062824 | W6: =OFFSET(FS!P106,0,0+E$6-B$6) -> 1.2077922 | X6: =AVERAGE(OFFSET(FS!P106,0,-2+E$6-B$6):OFFSET(FS!P106,0,E$6-B$6)) -> 0.59135574 | Y6: =AVERAGE(OFFSET(FS!P106,0,-4+E$6-B$6):OFFSET(FS!P106,0,E$6-B$6)) -> 0.41258751 | Z6: =OFFSET(FS!P117,0,0+E$6-B$6) -> 0.00026053704 | AA6: =AVERAGE(OFFSET(FS!P117,0,-2+E$6-B$6):OFFSET(FS!P117,0,E$6-B$6)) -> 0.00057888117 | AB6: =AVERAGE(OFFSET(FS!P117,0,-4+E$6-B$6):OFFSET(FS!P117,0,E$6-B$6)) -> 0.0011313461 | AC6: =OFFSET(FS!P166,0,0+E$6-B$6) -> 0.34612342 | AD6: =AVERAGE(OFFSET(FS!P166,0,-2+E$6-B$6):OFFSET(FS!P166,0,E$6-B$6)) -> 0.40239944 | AE6: =AVERAGE(OFFSET(FS!P166,0,-4+E$6-B$6):OFFSET(FS!P166,0,E$6-B$6)) -> 0.38312601 | AF6: =OFFSET(FS!P167,0,0+E$6-B$6) -> 0.52934059 | AG6: =AVERAGE(OFFSET(FS!P167,0,-2+E$6-B$6):OFFSET(FS!P167,0,E$6-B$6)) -> 0.68437052 | AH6: =AVERAGE(OFFSET(FS!P167,0,-4+E$6-B$6):OFFSET(FS!P167,0,E$6-B$6)) -> 0.63524481 | AI6: =OFFSET(FS!P168,0,0+E$6-B$6) -> 0.37342832 | AJ6: =AVERAGE(OFFSET(FS!P168,0,-2+E$6-B$6):OFFSET(FS!P168,0,E$6-B$6)) -> 0.57793969 | AK6: =AVERAGE(OFFSET(FS!P168,0,-4+E$6-B$6):OFFSET(FS!P168,0,E$6-B$6)) -> 0.58309367 | AL6: =OFFSET(FS!P171,0,0+E$6-B$6) -> 3.1467247 | AM6: =AVERAGE(OFFSET(FS!P171,0,-2+E$6-B$6):OFFSET(FS!P171,0,E$6-B$6)) -> 3.007376 | AN6: =AVERAGE(OFFSET(FS!P171,0,-4+E$6-B$6):OFFSET(FS!P171,0,E$6-B$6)) -> 3.3399622 | AO6: =OFFSET(FS!P172,0,0+E$6-B$6) -> 6.0928093 | AP6: =AVERAGE(OFFSET(FS!P172,0,-2+E$6-B$6):OFFSET(FS!P172,0,E$6-B$6)) -> 6.3097023 | AQ6: =AVERAGE(OFFSET(FS!P172,0,-4+E$6-B$6):OFFSET(FS!P172,0,E$6-B$6)) -> 6.4766177 | AR6: =OFFSET(FS!P173,0,0+E$6-B$6) -> 6.1582067 | AS6: =AVERAGE(OFFSET(FS!P173,0,-2+E$6-B$6):OFFSET(FS!P173,0,E$6-B$6)) -> 7.0635226 | AT6: =AVERAGE(OFFSET(FS!P173,0,-4+E$6-B$6):OFFSET(FS!P173,0,E$6-B$6)) -> 6.5392154 | AU6: ='Sharpe, Sortino'!O23 -> 3.6648618 | AV6: ='Sharpe, Sortino'!P23 -> 1.1029148 | AW6: ='Sharpe, Sortino'!Q23 -> 1.4409924 | AX6: ='Sharpe, Sortino'!O40 -> 7.9692357 | AY6: ='Sharpe, Sortino'!P40 -> 1.9982805 | AZ6: ='Sharpe, Sortino'!Q40 -> 2.2423037

Sheet FS
F1: < Figures are in millions >
F2: Y/E 31/01 | U2: Annualized
F3: 2014 | G3: 2015 | H3: 2016 | I3: 2017 | J3: 2018 | K3: 2019 | L3: 2020 | M3: 2021 | N3: 2022 | O3: 2023 | P3: 2024 | R3: Average | S3: Median | T3: CAGR | U3: Std Dev
B5: Revenue By Geography
C6: United States | F6: 727 | G6: 791 | H6: 643 | I6: 904 | J6: 1274 | K6: 1506 | L6: 886 | M6: 3214 | N6: 4349 | O6: 8292 | P6: 26966
C7: Taiwan | F7: 1321 | G7: 1594 | H7: 1912 | I7: 2546 | J7: 2991 | K7: 3360 | L7: 3025 | M7: 4531 | N7: 8544 | O7: 6986 | P7: 13405
C8: China (inc. HK) | F8: 794 | G8: 922 | H8: 806 | I8: 1305 | J8: 1896 | K8: 2801 | L8: 2731 | M8: 3886 | N8: 7111 | O8: 5785 | P8: 10306
C9: Other countries | F9: =675+295+318 -> 1288 | G9: =638+369+368 -> 1375 | H9: =749+482+418 -> 1649 | I9: =1010+659+486 -> 2155 | J9: =2066+768+719 -> 3553 | K9: =2368+914+767 -> 4049 | L9: 4276 | M9: 5044 | N9: 6910 | O9: 5911 | P9: 10245
B10: Total Revenues | F10: =SUM(F6:F9) -> 4130 | G10: =SUM(G6:G9) -> 4682 | H10: =SUM(H6:H9) -> 5010 | I10: =SUM(I6:I9) -> 6910 | J10: =SUM(J6:J9) -> 9714 | K10: =SUM(K6:K9) -> 11716 | L10: =SUM(L6:L9) -> 10918 | M10: =SUM(M6:M9) -> 16675 | ... P10: =SUM(P6:P9) -> 60922
B12: Revenue By Specific Segments
C13: Data Center | F13: 199 | G13: 317 | H13: 339 | I13: 830 | J13: 1932 | K13: 2932 | L13: 2983 | M13: 6696 | N13: 10613 | O13: 15005 | P13: 47525
C14: Gaming | F14: 1511 | G14: 2058 | H14: 2818 | I14: 4060 | J14: 5513 | K14: 6246 | L14: 5518 | M14: 7759 | N14: 12462 | O14: 9067 | P14: 10447
C15: Professional Visualization | F15: 789 | G15: 795 | H15: 750 | I15: 835 | J15: 934 | K15: 1130 | L15: 1212 | M15: 1053 | N15: 2111 | O15: 1544 | P15: 1553
C16: Automotive | F16: 99 | G16: 183 | H16: 320 | I16: 487 | J16: 558 | K16: 641 | L16: 700 | M16: 536 | N16: 566 | O16: 903 | P16: 1091
C17: OEM & Other | F17: 1532 | G17: 1329 | H17: 783 | I17: 698 | J17: 777 | K17: 767 | L17: 505 | M17: 631 | N17: 1162 | O17: 455 | P17: 306
B18: Total Revenues | F18: =SUM(F13:F17) -> 4130 | G18: =SUM(G13:G17) -> 4682 | H18: =SUM(H13:H17) -> 5010 | I18: =SUM(I13:I17) -> 6910 | J18: =SUM(J13:J17) -> 9714 | K18: =SUM(K13:K17) -> 11716 | L18: =SUM(L13:L17) -> 10918 | M18: =SUM(M13:M17) -> 16675 | ... P18: =SUM(P13:P17) -> 60922
B20: Revenue by Segments
C21: Compute & Networking | F21: 398 | G21: 579 | H21: 559 | I21: 824 | J21: 1534 | K21: 3557 | L21: 3279 | M21: 6841 | N21: 11046 | O21: 15068 | P21: 47405
C22: Graphics | F22: 3468 | G22: 3839 | H22: 4187 | I22: 5822 | J22: 8137 | K22: 8159 | L22: 7639 | M22: 9834 | N22: 15868 | O22: 11906 | P22: 13517
C23: All Other | F23: 264 | G23: 264 | H23: 264 | I23: 264 | J23: 43 | K23: 0 | L23: 0 | M23: 0 | N23: 0 | O23: 0 | P23: 0
B24: Total Revenues | F24: =SUM(F21:F23) -> 4130 | G24: =SUM(G21:G23) -> 4682 | H24: =SUM(H21:H23) -> 5010 | I24: =SUM(I21:I23) -> 6910 | J24: =SUM(J21:J23) -> 9714 | K24: =SUM(K21:K23) -> 11716 | L24: =SUM(L21:L23) -> 10918 | M24: =SUM(M21:M23) -> 16675 | ... P24: =SUM(P21:P23) -> 60922
B26: Operating Income/(loss) Breakdown
C27: Compute & Networking | F27: -268 | G27: -254 | H27: -239 | I27: -9 | J27: 303 | K27: 1251 | L27: 751 | M27: 2548 | N27: 4598 | O27: 5083 | P27: 32016
C28: Graphics | F28: 835 | G28: 1113 | H28: 1344 | I28: 2180 | J28: 3507 | K28: 3417 | L28: 3267 | M28: 4612 | N28: 8492 | O28: 4552 | P28: 5846
C29: All Other | F29: -71 | G29: -100 | H29: -358 | I29: -237 | J29: -600 | K29: -864 | L29: -1172 | M29: -2628 | N29: -3049 | O29: -5411 | P29: -4890
B30: Total Operating Income | F30: =SUM(F27:F29) -> 496 | G30: =SUM(G27:G29) -> 759 | H30: =SUM(H27:H29) -> 747 | I30: =SUM(I27:I29) -> 1934 | J30: =SUM(J27:J29) -> 3210 | K30: =SUM(K27:K29) -> 3804 | L30: =SUM(L27:L29) -> 2846 | M30: =SUM(M27:M29) -> 4532 | ... P30: =SUM(P27:P29) -> 32972
C33: Composition By Geography
C34: United States | F34: =F6/F$10*100 -> 17.602906 | G34: =G6/G$10*100 -> 16.89449 | H34: =H6/H$10*100 -> 12.834331 | I34: =I6/I$10*100 -> 13.082489 | J34: =J6/J$10*100 -> 13.115092 | K34: =K6/K$10*100 -> 12.854216 | L34: =L6/L$10*100 -> 8.1150394 | M34: =M6/M$10*100 -> 19.274363 | ... P34: =P6/P$10*100 -> 44.263156 | R34: =AVERAGEIF(E34:Q34,"<>0") -> 18.630516
C35: Taiwan | F35: =F7/F$10*100 -> 31.985472 | G35: =G7/G$10*100 -> 34.04528 | H35: =H7/H$10*100 -> 38.163673 | I35: =I7/I$10*100 -> 36.845152 | J35: =J7/J$10*100 -> 30.790611 | K35: =K7/K$10*100 -> 28.67873 | L35: =L7/L$10*100 -> 27.70654 | M35: =M7/M$10*100 -> 27.172414 | ... P35: =P7/P$10*100 -> 22.003546 | R35: =AVERAGEIF(E35:Q35,"<>0") -> 30.457817
C36: China (including HK) | F36: =F8/F$10*100 -> 19.225182 | G36: =G8/G$10*100 -> 19.692439 | H36: =H8/H$10*100 -> 16.087824 | I36: =I8/I$10*100 -> 18.885673 | J36: =J8/J$10*100 -> 19.518221 | K36: =K8/K$10*100 -> 23.907477 | L36: =L8/L$10*100 -> 25.013739 | M36: =M8/M$10*100 -> 23.304348 | ... P36: =P8/P$10*100 -> 16.916713 | R36: =AVERAGEIF(E36:Q36,"<>0") -> 20.947217
C37: Other countries | F37: =F9/F$10*100 -> 31.186441 | G37: =G9/G$10*100 -> 29.367792 | H37: =H9/H$10*100 -> 32.914172 | I37: =I9/I$10*100 -> 31.186686 | J37: =J9/J$10*100 -> 36.576076 | K37: =K9/K$10*100 -> 34.559577 | L37: =L9/L$10*100 -> 39.164682 | M37: =M9/M$10*100 -> 30.248876 | ... P37: =P9/P$10*100 -> 16.816585 | R37: =AVERAGEIF(E37:Q37,"<>0") -> 29.96445
F38: =SUM(F34:F37) -> 100 | G38: =SUM(G34:G37) -> 100 | H38: =SUM(H34:H37) -> 100 | I38: =SUM(I34:I37) -> 100 | J38: =SUM(J34:J37) -> 100 | K38: =SUM(K34:K37) -> 100 | L38: =SUM(L34:L37) -> 100 | M38: =SUM(M34:M37) -> 100 | ... P38: =SUM(P34:P37) -> 100
C40: Composition By Specific Segments
C41: Data Center | F41: =F13/F$18*100 -> 4.8184019 | G41: =G13/G$18*100 -> 6.7706109 | H41: =H13/H$18*100 -> 6.7664671 | I41: =I13/I$18*100 -> 12.011577 | J41: =J13/J$18*100 -> 19.88882 | K41: =K13/K$18*100 -> 25.025606 | L41: =L13/L$18*100 -> 27.321854 | M41: =M13/M$18*100 -> 40.155922 | ... P41: =P13/P$18*100 -> 78.009586 | R41: =AVERAGEIF(E41:Q41,"<>0") -> 28.711772
C42: Gaming | F42: =F14/F$18*100 -> 36.585956 | G42: =G14/G$18*100 -> 43.955575 | H42: =H14/H$18*100 -> 56.247505 | I42: =I14/I$18*100 -> 58.755427 | J42: =J14/J$18*100 -> 56.75314 | K42: =K14/K$18*100 -> 53.31171 | L42: =L14/L$18*100 -> 50.540392 | M42: =M14/M$18*100 -> 46.530735 | ... P42: =P14/P$18*100 -> 17.148157 | R42: =AVERAGEIF(E42:Q42,"<>0") -> 45.431408
C43: Professional Visualization | F43: =F15/F$18*100 -> 19.104116 | G43: =G15/G$18*100 -> 16.979923 | H43: =H15/H$18*100 -> 14.97006 | I43: =I15/I$18*100 -> 12.083936 | J43: =J15/J$18*100 -> 9.6149887 | K43: =K15/K$18*100 -> 9.64493 | L43: =L15/L$18*100 -> 11.100934 | M43: =M15/M$18*100 -> 6.3148426 | ... P43: =P15/P$18*100 -> 2.5491612 | R43: =AVERAGEIF(E43:Q43,"<>0") -> 10.539129
C44: Automotive | F44: =F16/F$18*100 -> 2.3970944 | G44: =G16/G$18*100 -> 3.9085861 | H44: =H16/H$18*100 -> 6.3872255 | I44: =I16/I$18*100 -> 7.0477569 | J44: =J16/J$18*100 -> 5.7442866 | K44: =K16/K$18*100 -> 5.4711506 | L44: =L16/L$18*100 -> 6.4114307 | M44: =M16/M$18*100 -> 3.2143928 | ... P44: =P16/P$18*100 -> 1.7908145 | R44: =AVERAGEIF(E44:Q44,"<>0") -> 4.3475819
C45: OEM & Other | F45: =F17/F$18*100 -> 37.094431 | G45: =G17/G$18*100 -> 28.385305 | H45: =H17/H$18*100 -> 15.628743 | I45: =I17/I$18*100 -> 10.101302 | J45: =J17/J$18*100 -> 7.9987647 | K45: =K17/K$18*100 -> 6.5466029 | L45: =L17/L$18*100 -> 4.6253893 | M45: =M17/M$18*100 -> 3.7841079 | ... P45: =P17/P$18*100 -> 0.50228161 | R45: =AVERAGEIF(E45:Q45,"<>0") -> 10.970108
F46: =SUM(F41:F45) -> 100 | G46: =SUM(G41:G45) -> 100 | H46: =SUM(H41:H45) -> 100 | I46: =SUM(I41:I45) -> 100 | J46: =SUM(J41:J45) -> 100 | K46: =SUM(K41:K45) -> 100 | L46: =SUM(L41:L45) -> 100 | M46: =SUM(M41:M45) -> 100 | ... P46: =SUM(P41:P45) -> 100
C48: Composition By Segments
...

Sheet Sharpe, Sortino
B3: NVDA Monthly Price Changes (5 years) | L3: United States 10-Year Bond Yield
B4: https://www.investing.com/equities/nvidia-corp-historical-data | L4: https://www.investing.com/rates-bonds/u.s.-10-year-bond-yield-historical-data
B5: Feb'20 - Jan'24 | L5: Risk free rate average | O5: =[1]Sheet1!$E$6 -> 0.0246945 | S5: TEST (Manual calculation of Monthly Std Dev of Excess Returns - 5 Years)
F7: [1] | G7: [2] | H7: [1] - [2] | J7: [1] - [2] | S7: Sharpe | X7: Sortino
B8: Date | C8: Price | D8: Change % | F8: Change | G8: Monthly Risk free rate | H8: Monthly Excess returns | J8: Monthly Excess negative returns | S8: Average Monthly Excess Returns | U8: Difference Squared | V8: Monthly Std Dev of excess returns (σ) | X8: Average Monthly Excess Negative Returns | Y8: Difference Squared | Z8: Monthly Std Dev of excess returns (σ)
A9: 1 | B9: 45292 | C9: 61.53 | D9: 0.2424 | F9: =D9 -> 0.2424 | G9: =O$5/12 -> 0.002057875 | H9: =F9-G9 -> 0.24034212 | J9: =IF(H9<0,H9,"") | L9: Sharpe Ratio | O9: 1 Year | P9: 3 Years | Q9: 5 Years | S9: =AVERAGE(H9:H68) -> 0.056620458 | T9: 1 | U9: =(H9-S$9)^2 -> 0.033753651 | V9: =(U70/T68)^(1/2) -> 0.14325812 | X9: =AVERAGE(J9:J68) -> -0.10091287 | Y9: =IF(J9="","",(J9-X$9)^2) | Z9: =(Y70/(COUNT(Y9:Y69)-1))^(1/2) -> 0.092063293
A10: 2 | B10: 45261 | C10: 49.52 | D10: 0.0588 | F10: =D10 -> 0.0588 | G10: =O$5/12 -> 0.002057875 | H10: =F10-G10 -> 0.056742125 | J10: =IF(H10<0,H10,"") | T10: 2 | U10: =(H10-S$9)^2 -> 1.4802778e-08 | Y10: =IF(J10="","",(J10-X$9)^2)
A11: 3 | B11: 45231 | C11: 46.77 | D11: 0.1469 | F11: =D11 -> 0.1469 | G11: =O$5/12 -> 0.002057875 | H11: =F11-G11 -> 0.14484212 | J11: =IF(H11<0,H11,"") | L11: Monthly Std Dev of excess returns (σ) | O11: =STDEV.P(H9:H20) -> 0.12801246 | P11: =STDEV.P(H9:H44) -> 0.16353309 | Q11: =STDEV.P(H9:H68) -> 0.14325812 | T11: 3 | U11: =(H11-S$9)^2 -> 0.0077830625 | Y11: =IF(J11="","",(J11-X$9)^2)
A12: 4 | B12: 45200 | C12: 40.78 | D12: -0.0625 | F12: =D12 -> -0.0625 | G12: =O$5/12 -> 0.002057875 | H12: =F12-G12 -> -0.064557875 | J12: =IF(H12<0,H12,"") -> -0.064557875 | L12: Monthly Portfolio return (Rp) | O12: =(1+O19)^(1/12)-1 -> 0.084597814 | P12: =(1+P19)^(1/12)-1 -> 0.042587431 | Q12: =(1+Q19)^(1/12)-1 -> 0.047229 | T12: 4 | U12: =(H12-S$9)^2 -> 0.014684188 | Y12: =IF(J12="","",(J12-X$9)^2) -> 0.001321686
A13: 5 | B13: 45170 | C13: 43.5 | D13: -0.1187 | F13: =D13 -> -0.1187 | G13: =O$5/12 -> 0.002057875 | H13: =F13-G13 -> -0.12075788 | J13: =IF(H13<0,H13,"") -> -0.12075788 | L13: Monthly Risk-free return - US 10Yr Yield (Rf) | O13: =O20/12 -> 0.002057875 | P13: =P20/12 -> 0.002057875 | Q13: =Q20/12 -> 0.002057875 | T13: 5 | U13: =(H13-S$9)^2 -> 0.031463073 | Y13: =IF(J13="","",(J13-X$9)^2) -> 0.00039382402
A14: 6 | B14: 45139 | C14: 49.35 | D14: 0.0562 | F14: =D14 -> 0.0562 | G14: =O$5/12 -> 0.002057875 | H14: =F14-G14 -> 0.054142125 | J14: =IF(H14<0,H14,"") | L14: Excess return (Rp - Rf) | O14: =O12-O13 -> 0.082539939 | P14: =P12-P13 -> 0.040529556 | Q14: =Q12-Q13 -> 0.045171125 | T14: 6 | U14: =(H14-S$9)^2 -> 6.1421361e-06 | Y14: =IF(J14="","",(J14-X$9)^2)
A15: 7 | B15: 45108 | C15: 46.73 | D15: 0.1047 | F15: =D15 -> 0.1047 | G15: =O$5/12 -> 0.002057875 | H15: =F15-G15 -> 0.10264213 | J15: =IF(H15<0,H15,"") | T15: 7 | U15: =(H15-S$9)^2 -> 0.0021179938 | Y15: =IF(J15="","",(J15-X$9)^2)
A16: 8 | B16: 45078 | C16: 42.3 | D16: 0.1181 | F16: =D16 -> 0.1181 | G16: =O$5/12 -> 0.002057875 | H16: =F16-G16 -> 0.11604212 | J16: =IF(H16<0,H16,"") | L16: Monthly Sharpe Ratio ( [Rp - Rf] / σ ) | O16: =O14/O11 -> 0.6447805 | P16: =P14/P11 -> 0.24783704 | Q16: =Q14/Q11 -> 0.31531283 | T16: 8 | U16: =(H16-S$9)^2 -> 0.0035309345 | Y16: =IF(J16="","",(J16-X$9)^2)
A17: 9 | B17: 45047 | C17: 37.83 | D17: 0.3634 | F17: =D17 -> 0.3634 | G17: =O$5/12 -> 0.002057875 | H17: =F17-G17 -> 0.36134213 | J17: =IF(H17<0,H17,"") | T17: 9 | U17: =(H17-S$9)^2 -> 0.092855294 | Y17: =IF(J17="","",(J17-X$9)^2)
A18: 10 | B18: 45017 | C18: 27.75 | D18: -0.001 | F18: =D18 -> -0.001 | G18: =O$5/12 -> 0.002057875 | H18: =F18-G18 -> -0.003057875 | J18: =IF(H18<0,H18,"") -> -0.003057875 | L18: Annualized Std Dev of excess returns (σ) | O18: =O11*12^(1/2) -> 0.44344818 | P18: =P11*12^(1/2) -> 0.56649524 | Q18: =Q11*12^(1/2) -> 0.4962607 | T18: 10 | U18: =(H18-S$9)^2 -> 0.0035615035 | Y18: =IF(J18="","",(J18-X$9)^2) -> 0.009575601
A19: 11 | B19: 44986 | C19: 27.78 | D19: 0.1965 | F19: =D19 -> 0.1965 | G19: =O$5/12 -> 0.002057875 | H19: =F19-G19 -> 0.19444212 | J19: =IF(H19<0,H19,"") | L19: Annualized Portfolio return (Rp) | O19: =($C$9/$C$20)^(1/($A$20/12))-1 -> 1.6498708 | P19: =($C$9/$C$44)^(1/($A$44/12))-1 -> 0.64949051 | Q19: =($C$9/$C$68)^(1/($A$68/12))-1 -> 0.73980239 | T19: 11 | U19: =(H19-S$9)^2 -> 0.018994812 | Y19: =IF(J19="","",(J19-X$9)^2)
A20: 12 | B20: 44958 | C20: 23.22 | D20: 0.1883 | F20: =D20 -> 0.1883 | G20: =O$5/12 -> 0.002057875 | H20: =F20-G20 -> 0.18624213 | J20: =IF(H20<0,H20,"") | L20: Annualized Risk-free return - US 10Yr Yield (Rf) | O20: =$O$5 -> 0.0246945 | P20: =$O$5 -> 0.0246945 | Q20: =$O$5 -> 0.0246945 | T20: 12 | U20: =(H20-S$9)^2 -> 0.016801776 | Y20: =IF(J20="","",(J20-X$9)^2)
A21: 13 | B21: 44927 | C21: 19.54 | D21: 0.3369 | F21: =D21 -> 0.3369 | G21: =O$5/12 -> 0.002057875 | H21: =F21-G21 -> 0.33484212 | J21: =IF(H21<0,H21,"") | L21: Excess return (Rp - Rf) | O21: =O19-O20 -> 1.6251763 | P21: =P19-P20 -> 0.62479601 | Q21: =Q19-Q20 -> 0.71510789 | T21: 13 | U21: =(H21-S$9)^2 -> 0.077407296 | Y21: =IF(J21="","",(J21-X$9)^2)
A22: 14 | B22: 44896 | C22: 14.61 | D22: -0.1364 | F22: =D22 -> -0.1364 | G22: =O$5/12 -> 0.002057875 | H22: =F22-G22 -> -0.13845788 | J22: =IF(H22<0,H22,"") -> -0.13845788 | T22: 14 | U22: =(H22-S$9)^2 -> 0.038055556 | Y22: =IF(J22="","",(J22-X$9)^2) -> 0.001409627
A23: 15 | B23: 44866 | C23: 16.92 | D23: 0.2538 | F23: =D23 -> 0.2538 | G23: =O$5/12 -> 0.002057875 | H23: =F23-G23 -> 0.25174212 | J23: =IF(H23<0,H23,"") | L23: Annualized Sharpe Ratio ( [Rp - Rf] / σ ) | O23: =O21/O18 -> 3.6648618 | P23: =P21/P18 -> 1.1029148 | Q23: =Q21/Q18 -> 1.4409924 | T23: 15 | U23: =(H23-S$9)^2 -> 0.038072465 | Y23: =IF(J23="","",(J23-X$9)^2)
A24: 16 | B24: 44835 | C24: 13.5 | D24: 0.1119 | F24: =D24 -> 0.1119 | G24: =O$5/12 -> 0.002057875 | H24: =F24-G24 -> 0.10984212 | J24: =IF(H24<0,H24,"") | T24: 16 | U24: =(H24-S$9)^2 -> 0.0028325458 | Y24: =IF(J24="","",(J24-X$9)^2)
A25: 17 | B25: 44805 | C25: 12.14 | D25: -0.1958 | F25: =D25 -> -0.1958 | G25: =O$5/12 -> 0.002057875 | H25: =F25-G25 -> -0.19785787 | J25: =IF(H25<0,H25,"") -> -0.19785787 | T25: 17 | U25: =(H25-S$9)^2 -> 0.064759222 | Y25: =IF(J25="","",(J25-X$9)^2) -> 0.009398333
A26: 18 | B26: 44774 | C26: 15.09 | D26: -0.169 | F26: =D26 -> -0.169 | G26: =O$5/12 -> 0.002057875 | H26: =F26-G26 -> -0.17105787 | J26: =IF(H26<0,H26,"") -> -0.17105787 | L26: Sortino Ratio | O26: 1 Year | P26: 3 Years | Q26: 5 Years | T26: 18 | U26: =(H26-S$9)^2 -> 0.051837423 | Y26: =IF(J26="","",(J26-X$9)^2) -> 0.004920321
A27: 19 | B27: 44743 | C27: 18.16 | D27: 0.1982 | F27: =D27 -> 0.1982 | G27: =O$5/12 -> 0.002057875 | H27: =F27-G27 -> 0.19614213 | J27: =IF(H27<0,H27,"") | T27: 19 | U27: =(H27-S$9)^2 -> 0.019466295 | Y27: =IF(J27="","",(J27-X$9)^2)
A28: 20 | B28: 44713 | C28: 15.16 | D28: -0.1881 | F28: =D28 -> -0.1881 | G28: =O$5/12 -> 0.002057875 | H28: =F28-G28 -> -0.19015788 | J28: =IF(H28<0,H28,"") -> -0.19015788 | L28: Monthly Std Dev of excess negative returns (σd) | O28: =_xlfn.STDEV.S(J9:J20) -> 0.058869885 | P28: =_xlfn.STDEV.S(J9:J44) -> 0.090259137 | Q28: =_xlfn.STDEV.S(J9:J68) -> 0.092063293 | T28: 20 | U28: =(H28-S$9)^2 -> 0.060899546 | Y28: =IF(J28="","",(J28-X$9)^2) -> 0.00796467
A29: 21 | B29: 44682 | C29: 18.67 | D29: 0.0067 | F29: =D29 -> 0.0067 | G29: =O$5/12 -> 0.002057875 | H29: =F29-G29 -> 0.004642125 | J29: =IF(H29<0,H29,"") | L29: Monthly Portfolio return (Rp) | O29: =(1+O36)^(1/12)-1 -> 0.084597814 | P29: =(1+P36)^(1/12)-1 -> 0.042587431 | Q29: =(1+Q36)^(1/12)-1 -> 0.047229 | T29: 21 | U29: =(H29-S$9)^2 -> 0.0027017471 | Y29: =IF(J29="","",(J29-X$9)^2)
A30: 22 | B30: 44652 | C30: 18.55 | D30: -0.3203 | F30: =D30 -> -0.3203 | G30: =O$5/12 -> 0.002057875 | H30: =F30-G30 -> -0.32235788 | J30: =IF(H30<0,H30,"") -> -0.32235788 | L30: Monthly Risk-free return - US 10Yr Yield (Rf) | O30: =O37/12 -> 0.002057875 | P30: =P37/12 -> 0.002057875 | Q30: =Q37/12 -> 0.002057875 | T30: 22 | U30: =(H30-S$9)^2 -> 0.14362458 | Y30: =IF(J30="","",(J30-X$9)^2) -> 0.049037888
A31: 23 | B31: 44621 | C31: 27.29 | D31: 0.119 | F31: =D31 -> 0.119 | G31: =O$5/12 -> 0.002057875 | H31: =F31-G31 -> 0.11694212 | J31: =IF(H31<0,H31,"") | L31: Excess return (Rp - Rf) | O31: =O29-O30 -> 0.082539939 | P31: =P29-P30 -> 0.040529556 | Q31: =Q29-Q30 -> 0.045171125 | T31: 23 | U31: =(H31-S$9)^2 -> 0.0036387035 | Y31: =IF(J31="","",(J31-X$9)^2)
A32: 24 | B32: 44593 | C32: 24.39 | D32: -0.0041 | F32: =D32 -> -0.0041 | G32: =O$5/12 -> 0.002057875 | H32: =F32-G32 -> -0.006157875 | J32: =IF(H32<0,H32,"") -> -0.006157875 | T32: 24 | U32: =(H32-S$9)^2 -> 0.0039411191 | Y32: =IF(J32="","",(J32-X$9)^2) -> 0.00897851
A33: 25 | B33: 44562 | C33: 24.49 | D33: -0.1675 | F33: =D33 -> -0.1675 | G33: =O$5/12 -> 0.002057875 | H33: =F33-G33 -> -0.16955787 | J33: =IF(H33<0,H33,"") -> -0.16955787 | L33: Monthly Sortino Ratio ( [Rp - Rf] / σ ) | O33: =O31/O28 -> 1.4020741 | P33: =P31/P28 -> 0.44903549 | Q33: =Q31/Q28 -> 0.49065293 | T33: 25 | U33: =(H33-S$9)^2 -> 0.051156638 | Y33: =IF(J33="","",(J33-X$9)^2) -> 0.004712136
A34: 26 | B34: 44531 | C34: 29.41 | D34: -0.0999 | F34: =D34 -> -0.0999 | G34: =O$5/12 -> 0.002057875 | H34: =F34-G34 -> -0.10195788 | J34: =IF(H34<0,H34,"") -> -0.10195788 | T34: 26 | U34: =(H34-S$9)^2 -> 0.025147088 | Y34: =IF(J34="","",(J34-X$9)^2) -> 1.092025e-06
A35: 27 | B35: 44501 | C35: 32.68 | D35: 0.2781 | F35: =D35 -> 0.2781 | G35: =O$5/12 -> 0.002057875 | H35: =F35-G35 -> 0.27604213 | J35: =IF(H35<0,H35,"") | L35: Annualized Std Dev of excess negative returns (σ) | O35: =O28*12^(1/2) -> 0.20393126 | P35: =P28*12^(1/2) -> 0.31266682 | Q35: =Q28*12^(1/2) -> 0.3189166 | T35: 27 | U35: =(H35-S$9)^2 -> 0.048145868 | Y35: =IF(J35="","",(J35-X$9)^2)
A36: 28 | B36: 44470 | C36: 25.57 | D36: 0.2342 | F36: =D36 -> 0.2342 | G36: =O$5/12 -> 0.002057875 | H36: =F36-G36 -> 0.23214213 | J36: =IF(H36<0,H36,"") | L36: Annualized Portfolio return (Rp) | O36: =($C$9/$C$20)^(1/($A$20/12))-1 -> 1.6498708 | P36: =($C$9/$C$44)^(1/($A$44/12))-1 -> 0.64949051 | Q36: =($C$9/$C$68)^(1/($A$68/12))-1 -> 0.73980239 | T36: 28 | U36: =(H36-S$9)^2 -> 0.030807855 | Y36: =IF(J36="","",(J36-X$9)^2)
A37: 29 | B37: 44440 | C37: 20.72 | D37: -0.0746 | F37: =D37 -> -0.0746 | G37: =O$5/12 -> 0.002057875 | H37: =F37-G37 -> -0.076657875 | J37: =IF(H37<0,H37,"") -> -0.076657875 | L37: Annualized Risk-free return - US 10Yr Yield (Rf) | O37: =$O$5 -> 0.0246945 | P37: =$O$5 -> 0.0246945 | Q37: =$O$5 -> 0.0246945 | T37: 29 | U37: =(H37-S$9)^2 -> 0.017763114 | Y37: =IF(J37="","",(J37-X$9)^2) -> 0.00058830503
A38: 30 | B38: 44409 | C38: 22.39 | D38: 0.148 | F38: =D38 -> 0.148 | G38: =O$5/12 -> 0.002057875 | H38: =F38-G38 -> 0.14594213 | J38: =IF(H38<0,H38,"") | L38: Excess return (Rp - Rf) | O38: =O36-O37 -> 1.6251763 | P38: =P36-P37 -> 0.62479601 | Q38: =Q36-Q37 -> 0.71510789 | T38: 30 | U38: =(H38-S$9)^2 -> 0.0079783601 | Y38: =IF(J38="","",(J38-X$9)^2)
A39: 31 | B39: 44378 | C39: 19.5 | D39: -0.0252 | F39: =D39 -> -0.0252 | G39: =O$5/12 -> 0.002057875 | H39: =F39-G39 -> -0.027257875 | J39: =IF(H39<0,H39,"") -> -0.027257875 | T39: 31 | U39: =(H39-S$9)^2 -> 0.0070355748 | Y39: =IF(J39="","",(J39-X$9)^2) -> 0.005425059
A40: 32 | B40: 44348 | C40: 20 | D40: 0.2313 | F40: =D40 -> 0.2313 | G40: =O$5/12 -> 0.002057875 | H40: =F40-G40 -> 0.22924212 | J40: =IF(H40<0,H40,"") | L40: Annualized Sortino Ratio ( [Rp - Rf] / σd ) | O40: =O38/O35 -> 7.9692357 | P40: =P38/P35 -> 1.9982805 | Q40: =Q38/Q35 -> 2.2423037 | T40: 32 | U40: =(H40-S$9)^2 -> 0.02979824 | Y40: =IF(J40="","",(J40-X$9)^2)
A41: 33 | B41: 44317 | C41: 16.24 | D41: 0.0823 | F41: =D41 -> 0.0823 | G41: =O$5/12 -> 0.002057875 | H41: =F41-G41 -> 0.080242125 | J41: =IF(H41<0,H41,"") | T41: 33 | U41: =(H41-S$9)^2 -> 0.00055798314 | Y41: =IF(J41="","",(J41-X$9)^2)
A42: 34 | B42: 44287 | C42: 15.01 | D42: 0.1245 | F42: =D42 -> 0.1245 | G42: =O$5/12 -> 0.002057875 | H42: =F42-G42 -> 0.12244212 | J42: =IF(H42<0,H42,"") | T42: 34 | U42: =(H42-S$9)^2 -> 0.0043324918 | Y42: =IF(J42="","",(J42-X$9)^2)
A43: 35 | B43: 44256 | C43: 13.35 | D43: -0.0267 | F43: =D43 -> -0.0267 | G43: =O$5/12 -> 0.002057875 | H43: =F43-G43 -> -0.028757875 | J43: =IF(H43<0,H43,"") -> -0.028757875 | T43: 35 | U43: =(H43-S$9)^2 -> 0.0072894598 | Y43: =IF(J43="","",(J43-X$9)^2) -> 0.005206344
...

Sheet Projection
F1: < Figures are in millions >
F2: Y/E 31/01
F3: 2014 | G3: 2015 | H3: 2016 | I3: 2017 | J3: 2018 | K3: 2019 | L3: 2020 | M3: 2021 | N3: 2022 | O3: 2023 | P3: 2024 | Q3: 2025 | R3: 2026 | S3: 2027 | T3: 2028 | U3: 2029 | V3: 2030 | W3: 2031 | X3: 2032 | Y3: 2033 | Z3: 2034 | AA3: 2035 | AC3: CAGR
T6: Average Growth Rate = | U6: =FS!R65 -> 35.288262 | V6: %
B7: P&L
B8: Revenue | F8: 4130 | G8: 4682 | H8: 5010 | I8: 6910 | J8: 9714 | K8: 11716 | L8: 10918 | M8: 16675 | N8: 26914 | O8: 26974 | P8: 60922 | Q8: =P8*(1+$U6/100) -> 82420.315 | R8: =Q8*(1+$U6/100) -> 111505.01 | S8: =R8*(1+$U6/100) -> 150853.19 | T8: =S8*(1+$U6/100) -> 204086.66 | U8: =T8*(1+$U6/100) -> 276105.3 | V8: =U8*(1+$U6/100) -> 373538.06 | W8: =V8*(1+$U6/100) -> 505353.15 | X8: =W8*(1+$U6/100) -> 683683.49 | ... AA8: =Z8*(1+$U6/100) -> 1692916.1
B9: Cost of Revenue | F9: 1862 | G9: 2083 | H9: 2199 | I9: 2847 | J9: 3892 | K9: 4545 | L9: 4150 | M9: 6279 | N9: 9439 | O9: 11618 | P9: 16621 | Q9: =Q8-Q10 -> 32564.786 | R9: =R8-R10 -> 44056.333 | S9: =S8-S10 -> 59603.048 | T9: =T8-T10 -> 80635.927 | U9: =U8-U10 -> 109090.94 | V9: =V8-V10 -> 147587.24 | W9: =W8-W10 -> 199668.22 | X9: =X8-X10 -> 270127.66 | ... AA9: =AA8-AA10 -> 668881.84
B10: Gross Profit | F10: =F8-F9 -> 2268 | G10: =G8-G9 -> 2599 | H10: =H8-H9 -> 2811 | I10: =I8-I9 -> 4063 | J10: =J8-J9 -> 5822 | K10: =K8-K9 -> 7171 | L10: =L8-L9 -> 6768 | M10: =M8-M9 -> 10396 | ... P10: =P8-P9 -> 44301 | Q10: =Q8*($Q11/100) -> 49855.529 | R10: =R8*($Q11/100) -> 67448.678 | S10: =S8*($Q11/100) -> 91250.145 | T10: =T8*($Q11/100) -> 123450.73 | U10: =U8*($Q11/100) -> 167014.35 | V10: =V8*($Q11/100) -> 225950.82 | W10: =W8*($Q11/100) -> 305684.93 | X10: =X8*($Q11/100) -> 413555.83 | ... AA10: =AA8*($Q11/100) -> 1024034.3
C11: GP margin (%) | F11: =IFERROR(F10/F8*100,0) -> 54.915254 | G11: =IFERROR(G10/G8*100,0) -> 55.510466 | H11: =IFERROR(H10/H8*100,0) -> 56.107784 | I11: =IFERROR(I10/I8*100,0) -> 58.798842 | J11: =IFERROR(J10/J8*100,0) -> 59.934116 | K11: =IFERROR(K10/K8*100,0) -> 61.206897 | L11: =IFERROR(L10/L8*100,0) -> 61.989375 | M11: =IFERROR(M10/M8*100,0) -> 62.344828 | ... P11: =IFERROR(P10/P8*100,0) -> 72.717573 | Q11: =AVERAGE(E11:P11) -> 60.489369
B13: Research & Development | F13: 1336 | G13: 1360 | H13: 1331 | I13: 1463 | J13: 1797 | K13: 2376 | L13: 2829 | M13: 3924 | N13: 5268 | O13: 7339 | P13: 8675
B14: Sales, general & admin | F14: 436 | G14: 480 | H14: 602 | I14: 663 | J14: 815 | K14: 991 | L14: 1093 | M14: 1940 | N14: 2166 | O14: =2440 -> 2440 | P14: 2654
B15: Restructuring & other charges | F15: 0 | G15: 0 | H15: 131 | I15: 3 | J15: 0 | K15: 0 | L15: 0 | M15: 0 | N15: 0 | O15: 0 | P15: 0
B16: Acquisition termination cost | F16: 0 | G16: 0 | H16: 0 | I16: 0 | J16: 0 | K16: 0 | L16: 0 | M16: 0 | N16: 0 | O16: 1353 | P16: 0
B17: Total Cost & Expenses | F17: =SUM(F13:F16) -> 1772 | G17: =SUM(G13:G16) -> 1840 | H17: =SUM(H13:H16) -> 2064 | I17: =SUM(I13:I16) -> 2129 | J17: =SUM(J13:J16) -> 2612 | K17: =SUM(K13:K16) -> 3367 | L17: =SUM(L13:L16) -> 3922 | M17: =SUM(M13:M16) -> 5864 | ... P17: =SUM(P13:P16) -> 11329 | Q17: =Q10-Q19 -> 27604.503 | R17: =R10-R19 -> 37345.652 | S17: =S10-S19 -> 50524.283 | T17: =T10-T19 -> 68353.425 | U17: =U10-U19 -> 92474.16 | V17: =V10-V19 -> 125106.68 | W17: =W10-W19 -> 169254.66 | X17: =X10-X19 -> 228981.69 | ... AA17: =AA10-AA19 -> 566997.45
B19: Operating Income | F19: =F10-F17 -> 496 | G19: =G10-G17 -> 759 | H19: =H10-H17 -> 747 | I19: =I10-I17 -> 1934 | J19: =J10-J17 -> 3210 | K19: =K10-K17 -> 3804 | L19: =L10-L17 -> 2846 | M19: =M10-M17 -> 4532 | ... P19: =P10-P17 -> 32972 | Q19: =Q8*($Q20/100) -> 22251.026 | R19: =R8*($Q20/100) -> 30103.026 | S19: =S8*($Q20/100) -> 40725.861 | T19: =T8*($Q20/100) -> 55097.31 | U19: =U8*($Q20/100) -> 74540.193 | V19: =V8*($Q20/100) -> 100844.13 | W19: =W8*($Q20/100) -> 136430.27 | X19: =X8*($Q20/100) -> 184574.14 | ... AA19: =AA8*($Q20/100) -> 457036.85
C20: Operating margin (%) | F20: =IFERROR(F19/F8*100,0) -> 12.009685 | G20: =IFERROR(G19/G8*100,0) -> 16.211021 | H20: =IFERROR(H19/H8*100,0) -> 14.91018 | I20: =IFERROR(I19/I8*100,0) -> 27.988423 | J20: =IFERROR(J19/J8*100,0) -> 33.04509 | K20: =IFERROR(K19/K8*100,0) -> 32.468419 | L20: =IFERROR(L19/L8*100,0) -> 26.067045 | M20: =IFERROR(M19/M8*100,0) -> 27.178411 | ... P20: =IFERROR(P19/P8*100,0) -> 54.121664 | Q20: =AVERAGE(E20:P20) -> 26.997017
B22: Other Income / (expense), Net | F22: =17-10+7 -> 14 | G22: =28-46+14 -> -4 | H22: =39-47+4 -> -4 | I22: =54-58-25 -> -29 | J22: =69-61-22 -> -14 | K22: =136-58+14 -> 92 | L22: =178-52-2 -> 124 | M22: =57-184+4 -> -123 | N22: =29-236+107 -> -100 | O22: =267-262-48 -> -43 | P22: =866-257+237 -> 846 | Q22: =Q8*(FS!$R$91/100) -> 338.94302 | R22: =R8*(FS!$R$91/100) -> 458.55012 | S22: =S8*(FS!$R$91/100) -> 620.36449 | T22: =T8*(FS!$R$91/100) -> 839.28034 | U22: =U8*(FS!$R$91/100) -> 1135.4478 | V22: =V8*(FS!$R$91/100) -> 1536.1276 | W22: =W8*(FS!$R$91/100) -> 2078.2003 | X22: =X8*(FS!$R$91/100) -> 2811.5611 | ... AA22: =AA8*(FS!$R$91/100) -> 6961.9015
B24: Income before taxation | F24: =F19+F22 -> 510 | G24: =G19+G22 -> 755 | H24: =H19+H22 -> 743 | I24: =I19+I22 -> 1905 | J24: =J19+J22 -> 3196 | K24: =K19+K22 -> 3896 | L24: =L19+L22 -> 2970 | M24: =M19+M22 -> 4409 | ... AA24: =AA19+AA22 -> 463998.75
B26: Income tax expense / (benefit) | F26: 70 | G26: 124 | H26: 129 | I26: 239 | J26: 149 | K26: -245 | L26: 174 | M26: 77 | N26: 189 | O26: -187 | P26: 4058 | Q26: =Q24-Q28 -> 1604.7793 | R26: =R24-R28 -> 2171.078 | S26: =S24-S28 -> 2937.2137 | T26: =T24-T28 -> 3973.7054 | U26: =U24-U28 -> 5375.957 | V26: =V24-V28 -> 7273.0387 | W26: =W24-W28 -> 9839.5677 | X26: =X24-X28 -> 13311.78 | ... AA26: =AA24-AA28 -> 32962.223
B28: Net Income | F28: =F24-F26 -> 440 | G28: =G24-G26 -> 631 | H28: =H24-H26 -> 614 | I28: =I24-I26 -> 1666 | J28: =J24-J26 -> 3047 | K28: =K24-K26 -> 4141 | L28: =L24-L26 -> 2796 | M28: =M24-M26 -> 4332 | ... P28: =P24-P26 -> 29760 | Q28: =Q8*($Q29/100) -> 20985.19 | R28: =R8*($Q29/100) -> 28390.499 | S28: =S8*($Q29/100) -> 38409.012 | T28: =T8*($Q29/100) -> 51962.885 | U28: =U8*($Q29/100) -> 70299.684 | V28: =V8*($Q29/100) -> 95107.22 | W28: =W8*($Q29/100) -> 128668.91 | X28: =X8*($Q29/100) -> 174073.93 | ... AA28: =AA8*($Q29/100) -> 431036.53
C29: Net income margin (%) | F29: =IFERROR(F28/F8*100,0) -> 10.653753 | G29: =IFERROR(G28/G8*100,0) -> 13.477147 | H29: =IFERROR(H28/H8*100,0) -> 12.255489 | I29: =IFERROR(I28/I8*100,0) -> 24.109986 | J29: =IFERROR(J28/J8*100,0) -> 31.367099 | K29: =IFERROR(K28/K8*100,0) -> 35.344828 | L29: =IFERROR(L28/L8*100,0) -> 25.609086 | M29: =IFERROR(M28/M8*100,0) -> 25.97901 | ... P29: =IFERROR(P28/P8*100,0) -> 48.849348 | Q29: =AVERAGE(E29:P29) -> 25.461186
C33: Valuation Multiples / Shareholder ratios
C34: No. of Shares | F34: =568*10*4 -> 22720 | G34: =545*10*4 -> 21800 | H34: =539*10*4 -> 21560 | I34: =585*10*4 -> 23400 | J34: =606*10*4 -> 24240 | K34: =2423*10 -> 24230 | L34: =2450*10 -> 24500 | M34: =2479*10 -> 24790 | N34: =2506*10 -> 25060 | O34: =2466*10 -> 24660 | P34: =2464*10 -> 24640 | Q34: =2464*10 -> 24640 | R34: =2464*10 -> 24640 | S34: =2464*10 -> 24640 | T34: =2464*10 -> 24640 | U34: =2464*10 -> 24640 | V34: =2464*10 -> 24640 | W34: =2464*10 -> 24640 | ... AA34: =2464*10 -> 24640
C35: Share Price | F35: 0.39 | G35: 0.48 | H35: 0.73 | I35: 2.73 | J35: 6.14 | K35: 3.59 | L35: 5.91 | M35: 12.99 | N35: 24.49 | O35: 19.54 | P35: 61.53 | Q35: =Q36*$Q37 -> 40.327828 | R35: =R36*$Q37 -> 54.558818 | S35: =S36*$Q37 -> 73.811677 | T35: =T36*$Q37 -> 99.858534 | U35: =U36*$Q37 -> 135.09688 | V35: =V36*$Q37 -> 182.77021 | W35: =W36*$Q37 -> 247.26665 | X35: =X36*$Q37 -> 334.52275 | ... AA35: =AA36*$Q37 -> 828.335 | AC35: =((AA35/P35)^(1/($AA$3-$P$3))-1)*100 -> 26.662248
C36: EPS | F36: =IFERROR(F28/F34,0) -> 0.019366197 | G36: =IFERROR(G28/G34,0) -> 0.028944954 | H36: =IFERROR(H28/H34,0) -> 0.028478664 | I36: =IFERROR(I28/I34,0) -> 0.071196581 | J36: =IFERROR(J28/J34,0) -> 0.12570132 | K36: =IFERROR(K28/K34,0) -> 0.17090384 | L36: =IFERROR(L28/L34,0) -> 0.11412245 | M36: =IFERROR(M28/M34,0) -> 0.17474788 | ... AA36: =IFERROR(AA28/AA34,0) -> 17.493366
C37: P/E | F37: =F35/F36 -> 20.138182 | G37: =G35/G36 -> 16.583201 | H37: =H35/H36 -> 25.633225 | I37: =I35/I36 -> 38.344538 | J37: =J35/J36 -> 48.845947 | K37: =K35/K36 -> 21.005965 | L37: =L35/L36 -> 51.786481 | M37: =M35/M36 -> 74.335665 | ... P37: =P35/P36 -> 50.944194 | Q37: =AVERAGE(E37:P37) -> 47.35138

Sheet SWOT
O2: Notes
B3: Strengths
C4: Data Center
D5: - Handles compute-intensive workloads (AI, data analytics, graphics & scientific computing)
D6: - compute offerings (supercomputing platforms & servers)
E7: -- GPUs, DPUs
E8: -- NVIDIA AI Enterprise software | O8: Comprehensive suite of enterprise-grade AI software
E9: -- NVIDIA vGPU
E10: -- NVIDIA DGX cloud service
D11: - network offerings
E12: -- end to end platforms for InfiniBand & ethernet
C14: Gaming
D15: - RTX & GTX GPUs
D16: - NVIDIA DLSS (Deep Learning Super Sampling)
D17: - GeForce NOW cloud gaming
D18: - NVIDIA Tegra SoCs | O18: - SoCs (system-on-a-chip) & development services for game consoles
C20: Professional Visualization
D21: - NVIDIA Omniverse
C23: Automotive
D24: - DRIVE Hyperion
C26: Manufacturing
D27: - Fabless and contracting manufacturing strategy | O27: Partner with key suppliers on all phases of manufacturing process (wafer fabrication, assembly, testing & packaging)
D28: - Focus on product design, quality control, reliability, marketing & customer support
D29: - May place inventory orders for product components to secure future supply (in growth periods)
D30: - Supply chain is concentrated in Asia-Pacific region
E31: Foundries to produce semiconductor wafers
F32: -- Taiwan Semiconductor Manufacturing Co Ltd (TSMC) | O32: Utilize CoWoS technology for semiconductor packaging
F33: -- Samsung Electronics Co. Ltd
E34: Purchase of Memory
F35: -- Micron Technology Inc
F36: -- SK Hynix Inc | O36: South korea
E37: Assembly , Testing and packaging of final products
F38: -- Hon Hai Precision Industry Co Ltd
F39: -- Wistron Corporation
F40: -- Fabrinet
B43: Weaknesses
B47: Opportunities
C48: Artificial Intelligence
D49: - NVIDIA DGX cloud service
D50: - NVIDIA NeMo
...
